Workbook

Sheet Day 1 Scores
A1: Team # | B1: Team | C1: Captain | D1: Initials | E1: Golfer 1 | G1: Golfer 2 | I1: Golfer 3 | K1: Golfer 4 | M1: Golfer 5 | O1: Golfer 6 | Q1: Golfer 7 | S1: Golfer 8 | U1: SCORE
A2: 1 | B2: Just when I thought I was out, they pull me back in | C2: Paul Castergine | D2: PC | E2: Ludvig Aberg | F2: =+VLOOKUP(E2,Sheet1!$U$10:$W$105,3,FALSE)-72 -> -4 | G2: Brooks Koepka | H2: =+VLOOKUP(G2,Sheet1!$U$10:$W$105,3,FALSE)-72 -> 2 | I2: Tommy Fleetwood | J2: =+VLOOKUP(I2,Sheet1!$U$10:$W$105,3,FALSE)-72 -> 1 | K2: Patrick Cantlay | L2: =+VLOOKUP(K2,Sheet1!$U$10:$W$105,3,FALSE)-72 -> 2 | M2: Sergio Garcia | N2: =+VLOOKUP(M2,Sheet1!$U$10:$W$105,3,FALSE)-72 -> 0 | O2: Sergio Garcia | P2: =+VLOOKUP(O2,Sheet1!$U$10:$W$105,3,FALSE)-72 -> 0 | Q2: Jordan Spieth | R2: =+VLOOKUP(Q2,Sheet1!$U$10:$W$105,3,FALSE)-72 -> 1 | S2: Cameron Young | T2: =+VLOOKUP(S2,Sheet1!$U$10:$W$105,3,FALSE)-72 -> 0 | U2: =IFERROR(SMALL(E2:T2,1)+SMALL(E2:T2,2)+SMALL(E2:T2,3),IFERROR(SMALL(E2:T2,1)+SMALL(E2:T2,2),IFERROR(SMALL(E2:T2,1),"-"))) -> -4
A3: 2 | B3: Subpar Effort | C3: Nick Hooten | D3: NH | E3: Xander Schauffele | F3: =+VLOOKUP(E3,Sheet1!$U$10:$W$105,3,FALSE)-72 -> 1 | G3: Xander Schauffele | H3: =+VLOOKUP(G3,Sheet1!$U$10:$W$105,3,FALSE)-72 -> 1 | I3: Brooks Koepka | J3: =+VLOOKUP(I3,Sheet1!$U$10:$W$105,3,FALSE)-72 -> 2 | K3: Brooks Koepka | L3: =+VLOOKUP(K3,Sheet1!$U$10:$W$105,3,FALSE)-72 -> 2 | M3: Tony Finau | N3: =+VLOOKUP(M3,Sheet1!$U$10:$W$105,3,FALSE)-72 -> 3 | O3: Tony Finau | P3: =+VLOOKUP(O3,Sheet1!$U$10:$W$105,3,FALSE)-72 -> 3 | Q3: Cameron Young | R3: =+VLOOKUP(Q3,Sheet1!$U$10:$W$105,3,FALSE)-72 -> 0 | S3: Maverick McNealy | T3: =+VLOOKUP(S3,Sheet1!$U$10:$W$105,3,FALSE)-72 -> 0 | U3: =IFERROR(SMALL(E3:T3,1)+SMALL(E3:T3,2)+SMALL(E3:T3,3),IFERROR(SMALL(E3:T3,1)+SMALL(E3:T3,2),IFERROR(SMALL(E3:T3,1),"-"))) -> 1
A4: 3 | B4: Minnesota Miracle | C4: Thad Williams | D4: TW | E4: Collin Morikawa | F4: =+VLOOKUP(E4,Sheet1!$U$10:$W$105,3,FALSE)-72 -> 0 | G4: Hideki Matsuyama | H4: =+VLOOKUP(G4,Sheet1!$U$10:$W$105,3,FALSE)-72 -> 1 | I4: Hideki Matsuyama | J4: =+VLOOKUP(I4,Sheet1!$U$10:$W$105,3,FALSE)-72 -> 1 | K4: Brooks Koepka | L4: =+VLOOKUP(K4,Sheet1!$U$10:$W$105,3,FALSE)-72 -> 2 | M4: Robert MacIntyre | N4: =+VLOOKUP(M4,Sheet1!$U$10:$W$105,3,FALSE)-72 -> 3 | O4: Will Zalatoris | P4: =+VLOOKUP(O4,Sheet1!$U$10:$W$105,3,FALSE)-72 -> 2 | Q4: Phil Mickelson | R4: =+VLOOKUP(Q4,Sheet1!$U$10:$W$105,3,FALSE)-72 -> 3 | S4: Laurie Canter | T4: =+VLOOKUP(S4,Sheet1!$U$10:$W$105,3,FALSE)-72 -> 5 | U4: =IFERROR(SMALL(E4:T4,1)+SMALL(E4:T4,2)+SMALL(E4:T4,3),IFERROR(SMALL(E4:T4,1)+SMALL(E4:T4,2),IFERROR(SMALL(E4:T4,1),"-"))) -> 2
A5: 4 | B5: Play the fade | C5: Dan Riordan | D5: DR | E5: Ludvig Aberg | F5: =+VLOOKUP(E5,Sheet1!$U$10:$W$105,3,FALSE)-72 -> -4 | G5: Justin Thomas | H5: =+VLOOKUP(G5,Sheet1!$U$10:$W$105,3,FALSE)-72 -> 1 | I5: Hideki Matsuyama | J5: =+VLOOKUP(I5,Sheet1!$U$10:$W$105,3,FALSE)-72 -> 1 | K5: Russell Henley | L5: =+VLOOKUP(K5,Sheet1!$U$10:$W$105,3,FALSE)-72 -> 7 | M5: Akshay Bhatia | N5: =+VLOOKUP(M5,Sheet1!$U$10:$W$105,3,FALSE)-72 -> -2 | O5: Akshay Bhatia | P5: =+VLOOKUP(O5,Sheet1!$U$10:$W$105,3,FALSE)-72 -> -2 | Q5: Corey Conners | R5: =+VLOOKUP(Q5,Sheet1!$U$10:$W$105,3,FALSE)-72 -> -4 | S5: Lucas Glover | T5: =+VLOOKUP(S5,Sheet1!$U$10:$W$105,3,FALSE)-72 -> 6 | U5: =IFERROR(SMALL(E5:T5,1)+SMALL(E5:T5,2)+SMALL(E5:T5,3),IFERROR(SMALL(E5:T5,1)+SMALL(E5:T5,2),IFERROR(SMALL(E5:T5,1),"-"))) -> -10
A6: 5 | B6: I Need A Pain Sponge | C6: Rob Schoen | D6: RS | E6: Justin Thomas | F6: =+VLOOKUP(E6,Sheet1!$U$10:$W$105,3,FALSE)-72 -> 1 | G6: Justin Thomas | H6: =+VLOOKUP(G6,Sheet1!$U$10:$W$105,3,FALSE)-72 -> 1 | I6: Shane Lowry | J6: =+VLOOKUP(I6,Sheet1!$U$10:$W$105,3,FALSE)-72 -> -1 | K6: Russell Henley | L6: =+VLOOKUP(K6,Sheet1!$U$10:$W$105,3,FALSE)-72 -> 7 | M6: Russell Henley | N6: =+VLOOKUP(M6,Sheet1!$U$10:$W$105,3,FALSE)-72 -> 7 | O6: Robert MacIntyre | P6: =+VLOOKUP(O6,Sheet1!$U$10:$W$105,3,FALSE)-72 -> 3 | Q6: Min Woo Lee | R6: =+VLOOKUP(Q6,Sheet1!$U$10:$W$105,3,FALSE)-72 -> -1 | S6: Will Zalatoris | T6: =+VLOOKUP(S6,Sheet1!$U$10:$W$105,3,FALSE)-72 -> 2 | U6: =IFERROR(SMALL(E6:T6,1)+SMALL(E6:T6,2)+SMALL(E6:T6,3),IFERROR(SMALL(E6:T6,1)+SMALL(E6:T6,2),IFERROR(SMALL(E6:T6,1),"-"))) -> -1
A7: 6 | B7: Fire Nico | C7: Dan Lahrman | D7: DL | E7: Viktor Hovland | F7: =+VLOOKUP(E7,Sheet1!$U$10:$W$105,3,FALSE)-72 -> -1 | G7: Viktor Hovland | H7: =+VLOOKUP(G7,Sheet1!$U$10:$W$105,3,FALSE)-72 -> -1 | I7: Jordan Spieth | J7: =+VLOOKUP(I7,Sheet1!$U$10:$W$105,3,FALSE)-72 -> 1 | K7: Jordan Spieth | L7: =+VLOOKUP(K7,Sheet1!$U$10:$W$105,3,FALSE)-72 -> 1 | M7: Hideki Matsuyama | N7: =+VLOOKUP(M7,Sheet1!$U$10:$W$105,3,FALSE)-72 -> 1 | O7: Hideki Matsuyama | P7: =+VLOOKUP(O7,Sheet1!$U$10:$W$105,3,FALSE)-72 -> 1 | Q7: Jason Day | R7: =+VLOOKUP(Q7,Sheet1!$U$10:$W$105,3,FALSE)-72 -> -2 | S7: Jason Day | T7: =+VLOOKUP(S7,Sheet1!$U$10:$W$105,3,FALSE)-72 -> -2 | U7: =IFERROR(SMALL(E7:T7,1)+SMALL(E7:T7,2)+SMALL(E7:T7,3),IFERROR(SMALL(E7:T7,1)+SMALL(E7:T7,2),IFERROR(SMALL(E7:T7,1),"-"))) -> -5
A8: 7 | B8: Gold Jacket, Green Jacket… | C8: Jon Schreiber | D8: JS | E8: Collin Morikawa | F8: =+VLOOKUP(E8,Sheet1!$U$10:$W$105,3,FALSE)-72 -> 0 | G8: Collin Morikawa | H8: =+VLOOKUP(G8,Sheet1!$U$10:$W$105,3,FALSE)-72 -> 0 | I8: Collin Morikawa | J8: =+VLOOKUP(I8,Sheet1!$U$10:$W$105,3,FALSE)-72 -> 0 | K8: Patrick Reed | L8: =+VLOOKUP(K8,Sheet1!$U$10:$W$105,3,FALSE)-72 -> -1 | M8: Maverick McNealy | N8: =+VLOOKUP(M8,Sheet1!$U$10:$W$105,3,FALSE)-72 -> 0 | O8: Cameron Young | P8: =+VLOOKUP(O8,Sheet1!$U$10:$W$105,3,FALSE)-72 -> 0 | Q8: Stephan Jaeger | R8: =+VLOOKUP(Q8,Sheet1!$U$10:$W$105,3,FALSE)-72 -> 0 | S8: Max Greyserman | T8: =+VLOOKUP(S8,Sheet1!$U$10:$W$105,3,FALSE)-72 -> -1 | U8: =IFERROR(SMALL(E8:T8,1)+SMALL(E8:T8,2)+SMALL(E8:T8,3),IFERROR(SMALL(E8:T8,1)+SMALL(E8:T8,2),IFERROR(SMALL(E8:T8,1),"-"))) -> -2
A9: 8 | B9: LaPlant | C9: Matt LaPlant | D9: ML | E9: Xander Schauffele | F9: =+VLOOKUP(E9,Sheet1!$U$10:$W$105,3,FALSE)-72 -> 1 | G9: Xander Schauffele | H9: =+VLOOKUP(G9,Sheet1!$U$10:$W$105,3,FALSE)-72 -> 1 | I9: Bryson DeChambeau | J9: =+VLOOKUP(I9,Sheet1!$U$10:$W$105,3,FALSE)-72 -> -3 | K9: Shane Lowry | L9: =+VLOOKUP(K9,Sheet1!$U$10:$W$105,3,FALSE)-72 -> -1 | M9: Corey Conners | N9: =+VLOOKUP(M9,Sheet1!$U$10:$W$105,3,FALSE)-72 -> -4 | O9: Sepp Straka | P9: =+VLOOKUP(O9,Sheet1!$U$10:$W$105,3,FALSE)-72 -> 6 | Q9: No Player | R9: =+VLOOKUP(Q9,Sheet1!$U$10:$W$105,3,FALSE)-72 -> 19 | S9: No Player | T9: =+VLOOKUP(S9,Sheet1!$U$10:$W$105,3,FALSE)-72 -> 19 | U9: =IFERROR(SMALL(E9:T9,1)+SMALL(E9:T9,2)+SMALL(E9:T9,3),IFERROR(SMALL(E9:T9,1)+SMALL(E9:T9,2),IFERROR(SMALL(E9:T9,1),"-"))) -> -8
A10: 9 | B10: Henley and the Double Eagles | C10: Adrian Chan | D10: AC | E10: Collin Morikawa | F10: =+VLOOKUP(E10,Sheet1!$U$10:$W$105,3,FALSE)-72 -> 0 | G10: Collin Morikawa | H10: =+VLOOKUP(G10,Sheet1!$U$10:$W$105,3,FALSE)-72 -> 0 | I10: Russell Henley | J10: =+VLOOKUP(I10,Sheet1!$U$10:$W$105,3,FALSE)-72 -> 7 | K10: Robert MacIntyre | L10: =+VLOOKUP(K10,Sheet1!$U$10:$W$105,3,FALSE)-72 -> 3 | M10: Robert MacIntyre | N10: =+VLOOKUP(M10,Sheet1!$U$10:$W$105,3,FALSE)-72 -> 3 | O10: Will Zalatoris | P10: =+VLOOKUP(O10,Sheet1!$U$10:$W$105,3,FALSE)-72 -> 2 | Q10: Will Zalatoris | R10: =+VLOOKUP(Q10,Sheet1!$U$10:$W$105,3,FALSE)-72 -> 2 | S10: No Player | T10: =+VLOOKUP(S10,Sheet1!$U$10:$W$105,3,FALSE)-72 -> 19 | U10: =IFERROR(SMALL(E10:T10,1)+SMALL(E10:T10,2)+SMALL(E10:T10,3),IFERROR(SMALL(E10:T10,1)+SMALL(E10:T10,2),IFERROR(SMALL(E10:T10,1),"-"))) -> 2
A11: 10 | B11: The Long Irons | C11: Kathryn Michalewicz | D11: KM | E11: Rory McIlroy | F11: =+VLOOKUP(E11,Sheet1!$U$10:$W$105,3,FALSE)-72 -> 0 | G11: Tommy Fleetwood | H11: =+VLOOKUP(G11,Sheet1!$U$10:$W$105,3,FALSE)-72 -> 1 | I11: Viktor Hovland | J11: =+VLOOKUP(I11,Sheet1!$U$10:$W$105,3,FALSE)-72 -> -1 | K11: Min Woo Lee | L11: =+VLOOKUP(K11,Sheet1!$U$10:$W$105,3,FALSE)-72 -> -1 | M11: Matthieu Pavon | N11: =+VLOOKUP(M11,Sheet1!$U$10:$W$105,3,FALSE)-72 -> 6 | O11: No Player | P11: =+VLOOKUP(O11,Sheet1!$U$10:$W$105,3,FALSE)-72 -> 19 | Q11: No Player | R11: =+VLOOKUP(Q11,Sheet1!$U$10:$W$105,3,FALSE)-72 -> 19 | S11: No Player | T11: =+VLOOKUP(S11,Sheet1!$U$10:$W$105,3,FALSE)-72 -> 19 | U11: =IFERROR(SMALL(E11:T11,1)+SMALL(E11:T11,2)+SMALL(E11:T11,3),IFERROR(SMALL(E11:T11,1)+SMALL(E11:T11,2),IFERROR(SMALL(E11:T11,1),"-"))) -> -2
A12: 11 | B12: Every day is Moving Day | C12: James Fetch | D12: JF | E12: Jon Rahm | F12: =+VLOOKUP(E12,Sheet1!$U$10:$W$105,3,FALSE)-72 -> 3 | G12: Bryson DeChambeau | H12: =+VLOOKUP(G12,Sheet1!$U$10:$W$105,3,FALSE)-72 -> -3 | I12: Brooks Koepka | J12: =+VLOOKUP(I12,Sheet1!$U$10:$W$105,3,FALSE)-72 -> 2 | K12: Jordan Spieth | L12: =+VLOOKUP(K12,Sheet1!$U$10:$W$105,3,FALSE)-72 -> 1 | M12: Patrick Reed | N12: =+VLOOKUP(M12,Sheet1!$U$10:$W$105,3,FALSE)-72 -> -1 | O12: Justin Rose | P12: =+VLOOKUP(O12,Sheet1!$U$10:$W$105,3,FALSE)-72 -> -7 | Q12: Nicolai Højgaard | R12: =+VLOOKUP(Q12,Sheet1!$U$10:$W$105,3,FALSE)-72 -> 4 | S12: Harris English | T12: =+VLOOKUP(S12,Sheet1!$U$10:$W$105,3,FALSE)-72 -> -2 | U12: =IFERROR(SMALL(E12:T12,1)+SMALL(E12:T12,2)+SMALL(E12:T12,3),IFERROR(SMALL(E12:T12,1)+SMALL(E12:T12,2),IFERROR(SMALL(E12:T12,1),"-"))) -> -12
A13: 12 | B13: Lafferty, Daniel | C13: Brad McLaughlin | D13: BM | E13: Ludvig Aberg | F13: =+VLOOKUP(E13,Sheet1!$U$10:$W$105,3,FALSE)-72 -> -4 | G13: Collin Morikawa | H13: =+VLOOKUP(G13,Sheet1!$U$10:$W$105,3,FALSE)-72 -> 0 | I13: Viktor Hovland | J13: =+VLOOKUP(I13,Sheet1!$U$10:$W$105,3,FALSE)-72 -> -1 | K13: Bryson DeChambeau | L13: =+VLOOKUP(K13,Sheet1!$U$10:$W$105,3,FALSE)-72 -> -3 | M13: Tony Finau | N13: =+VLOOKUP(M13,Sheet1!$U$10:$W$105,3,FALSE)-72 -> 3 | O13: Nick Dunlap | P13: =+VLOOKUP(O13,Sheet1!$U$10:$W$105,3,FALSE)-72 -> 18 | Q13: No Player | R13: =+VLOOKUP(Q13,Sheet1!$U$10:$W$105,3,FALSE)-72 -> 19 | S13: No Player | T13: =+VLOOKUP(S13,Sheet1!$U$10:$W$105,3,FALSE)-72 -> 19 | U13: =IFERROR(SMALL(E13:T13,1)+SMALL(E13:T13,2)+SMALL(E13:T13,3),IFERROR(SMALL(E13:T13,1)+SMALL(E13:T13,2),IFERROR(SMALL(E13:T13,1),"-"))) -> -8
... A40: 39 | B40: The Chipinskis | C40: Peter Sharpe | D40: PS | E40: Collin Morikawa | F40: =+VLOOKUP(E40,Sheet1!$U$10:$W$105,3,FALSE)-72 -> 0 | G40: Xander Schauffele | H40: =+VLOOKUP(G40,Sheet1!$U$10:$W$105,3,FALSE)-72 -> 1 | I40: Tom Hoge | J40: =+VLOOKUP(I40,Sheet1!$U$10:$W$105,3,FALSE)-72 -> 0 | K40: Tyrrell Hatton | L40: =+VLOOKUP(K40,Sheet1!$U$10:$W$105,3,FALSE)-72 -> -3 | M40: Min Woo Lee | N40: =+VLOOKUP(M40,Sheet1!$U$10:$W$105,3,FALSE)-72 -> -1 | O40: Shane Lowry | P40: =+VLOOKUP(O40,Sheet1!$U$10:$W$105,3,FALSE)-72 -> -1 | Q40: Brian Harman | R40: =+VLOOKUP(Q40,Sheet1!$U$10:$W$105,3,FALSE)-72 -> -1 | S40: Corey Conners | T40: =+VLOOKUP(S40,Sheet1!$U$10:$W$105,3,FALSE)-72 -> -4 | U40: =IFERROR(SMALL(E40:T40,1)+SMALL(E40:T40,2)+SMALL(E40:T40,3),IFERROR(SMALL(E40:T40,1)+SMALL(E40:T40,2),IFERROR(SMALL(E40:T40,1),"-"))) -> -8
U42: =+MAX(U2:U40) -> 2

Sheet Rosters (FINAL)
A1: Team # | B1: Team | C1: Captain | D1: Initials | E1: Golfer 1 | F1: Golfer 2 | G1: Golfer 3 | H1: Golfer 4 | I1: Golfer 5 | J1: Golfer 6 | K1: Golfer 7 | L1: Golfer 8
A2: 1 | B2: Just when I thought I was out, they pull me back in | C2: Paul Castergine | D2: PC | E2: Ludvig Aberg | F2: Brooks Koepka | G2: Tommy Fleetwood | H2: Patrick Cantlay | I2: Sergio Garcia | J2: Sergio Garcia | K2: Jordan Spieth | L2: Cameron Young
A3: 2 | B3: Subpar Effort | C3: Nick Hooten | D3: NH | E3: Xander Schauffele | F3: Xander Schauffele | G3: Brooks Koepka | H3: Brooks Koepka | I3: Tony Finau | J3: Tony Finau | K3: Cameron Young | L3: Maverick McNealy
A4: 3 | B4: Minnesota Miracle | C4: Thad Williams | D4: TW | E4: Collin Morikawa | F4: Hideki Matsuyama | G4: Hideki Matsuyama | H4: Brooks Koepka | I4: Robert MacIntyre | J4: Will Zalatoris | K4: Phil Mickelson | L4: Laurie Canter
A5: 4 | B5: Play the fade | C5: Dan Riordan | D5: DR | E5: Ludvig Aberg | F5: Justin Thomas | G5: Hideki Matsuyama | H5: Russell Henley | I5: Akshay Bhatia | J5: Akshay Bhatia | K5: Corey Conners | L5: Lucas Glover
A6: 5 | B6: I Need A Pain Sponge | C6: Rob Schoen | D6: RS | E6: Justin Thomas | F6: Justin Thomas | G6: Shane Lowry | H6: Russell Henley | I6: Russell Henley | J6: Robert MacIntyre | K6: Min Woo Lee | L6: Will Zalatoris
A7: 6 | B7: Fire Nico | C7: Dan Lahrman | D7: DL | E7: Viktor Hovland | F7: Viktor Hovland | G7: Jordan Spieth | H7: Jordan Spieth | I7: Hideki Matsuyama | J7: Hideki Matsuyama | K7: Jason Day | L7: Jason Day
A8: 7 | B8: Gold Jacket, Green Jacket… | C8: Jon Schreiber | D8: JS | E8: Collin Morikawa | F8: Collin Morikawa | G8: Collin Morikawa | H8: Patrick Reed | I8: Maverick McNealy | J8: Cameron Young | K8: Stephan Jaeger | L8: Max Greyserman
A9: 8 | B9: LaPlant | C9: Matt LaPlant | D9: ML | E9: Xander Schauffele | F9: Xander Schauffele | G9: Bryson DeChambeau | H9: Shane Lowry | I9: Corey Conners | J9: Sepp Straka | K9: No Player | L9: No Player
A10: 9 | B10: Henley and the Double Eagles | C10: Adrian Chan | D10: AC | E10: Collin Morikawa | F10: Collin Morikawa | G10: Russell Henley | H10: Robert MacIntyre | I10: Robert MacIntyre | J10: Will Zalatoris | K10: Will Zalatoris | L10: No Player
A11: 10 | B11: The Long Irons | C11: Kathryn Michalewicz | D11: KM | E11: Rory McIlroy | F11: Tommy Fleetwood | G11: Viktor Hovland | H11: Min Woo Lee | I11: Matthieu Pavon | J11: No Player | K11: No Player | L11: No Player
A12: 11 | B12: Every day in Moving Day | C12: James Fetch | D12: JF | E12: Jon Rahm | F12: Bryson DeChambeau | G12: Brooks Koepka | H12: Jordan Spieth | I12: Patrick Reed | J12: Justin Rose | K12: Nicolai Højgaard | L12: Harris English
A13: 12 | B13: Lafferty, Daniel | C13: Brad McLaughlin | D13: BM | E13: Ludvig Aberg | F13: Collin Morikawa | G13: Viktor Hovland | H13: Bryson DeChambeau | I13: Tony Finau | J13: Nick Dunlap | K13: No Player | L13: No Player
... A40: 39 | B40: The Chipinskis | C40: Peter Sharpe | D40: PS | E40: Collin Morikawa | F40: Xander Schauffele | G40: Tom Hoge | H40: Tyrrell Hatton | I40: Min Woo Lee | J40: Shane Lowry | K40: Brian Harman | L40: Corey Conners

Sheet Sheet1
D9: POS | E9: PLAYER | F9: SCORE | G9: TODAY | H9: THRU | I9: R1 | J9: R2 | K9: R3 | L9: R4 | M9: TOT | T9: Code | V9: Golfer
E10: 1 | F10: Justin Rose | G10: -7 | H10: -7 | I10: F | J10: 65 | K10: -- | L10: -- | M10: -- | N10: 65 | T10: 1 | U10: Scottie Scheffler | V10: Scottie Scheffler | W10: =+VLOOKUP(V10,$F$10:$N$104,5,FALSE) -> 68
E11: T2 | F11: Corey Conners | G11: -4 | H11: -4 | I11: F | J11: 68 | K11: -- | L11: -- | M11: -- | N11: 68 | T11: 2 | U11: Rory McIlroy | V11: Rory McIlroy | W11: =+VLOOKUP(V11,$F$10:$N$104,5,FALSE) -> 72
E12: T2 | F12: Scottie Scheffler | G12: -4 | H12: -4 | I12: F | J12: 68 | K12: -- | L12: -- | M12: -- | N12: 68 | T12: 3 | U12: Jon Rahm | V12: Jon Rahm | W12: =+VLOOKUP(V12,$F$10:$N$104,5,FALSE) -> 75
E13: T2 | F13: Ludvig Åberg | G13: -4 | H13: -4 | I13: F | J13: 68 | K13: -- | L13: -- | M13: -- | N13: 68 | T13: 4 | U13: Ludvig Aberg | V13: Ludvig Åberg | W13: =+VLOOKUP(V13,$F$10:$N$104,5,FALSE) -> 68
E14: T5 | F14: Tyrrell Hatton | G14: -3 | H14: -3 | I14: F | J14: 69 | K14: -- | L14: -- | M14: -- | N14: 69 | T14: 5 | U14: Collin Morikawa | V14: Collin Morikawa | W14: =+VLOOKUP(V14,$F$10:$N$104,5,FALSE) -> 72
E15: T5 | F15: Bryson DeChambeau | G15: -3 | H15: -3 | I15: F | J15: 69 | K15: -- | L15: -- | M15: -- | N15: 69 | T15: 6 | U15: Xander Schauffele | V15: Xander Schauffele | W15: =+VLOOKUP(V15,$F$10:$N$104,5,FALSE) -> 73
E16: T7 | F16: Aaron Rai | G16: -2 | H16: -2 | I16: F | J16: 70 | K16: -- | L16: -- | M16: -- | N16: 70 | T16: 7 | U16: Bryson DeChambeau | V16: Bryson DeChambeau | W16: =+VLOOKUP(V16,$F$10:$N$104,5,FALSE) -> 69
E17: T7 | F17: Harris English | G17: -2 | H17: -2 | I17: F | J17: 70 | K17: -- | L17: -- | M17: -- | N17: 70 | T17: 8 | U17: Justin Thomas | V17: Justin Thomas | W17: =+VLOOKUP(V17,$F$10:$N$104,5,FALSE) -> 73
E18: T7 | F18: Jason Day | G18: -2 | H18: -2 | I18: F | J18: 70 | K18: -- | L18: -- | M18: -- | N18: 70 | T18: 9 | U18: Joaquin Niemann | V18: Joaquín Niemann | W18: =+VLOOKUP(V18,$F$10:$N$104,5,FALSE) -> 72
E19: T7 | F19: Akshay Bhatia | G19: -2 | H19: -2 | I19: F | J19: 70 | K19: -- | L19: -- | M19: -- | N19: 70 | T19: 10 | U19: Hideki Matsuyama | V19: Hideki Matsuyama | W19: =+VLOOKUP(V19,$F$10:$N$104,5,FALSE) -> 73
E20: T11 | F20: Michael Kim | G20: -1 | H20: -1 | I20: F | J20: 71 | K20: -- | L20: -- | M20: -- | N20: 71 | T20: 11 | U20: Brooks Koepka | V20: Brooks Koepka | W20: =+VLOOKUP(V20,$F$10:$N$104,5,FALSE) -> 74
E21: T11 | F21: Davis Thompson | G21: -1 | H21: -1 | I21: F | J21: 71 | K21: -- | L21: -- | M21: -- | N21: 71 | T21: 12 | U21: Jordan Spieth | V21: Jordan Spieth | W21: =+VLOOKUP(V21,$F$10:$N$104,5,FALSE) -> 73
E22: T11 | F22: Cameron Smith | G22: -1 | H22: -1 | I22: F | J22: 71 | K22: -- | L22: -- | M22: -- | N22: 71 | T22: 13 | U22: Tommy Fleetwood | V22: Tommy Fleetwood | W22: =+VLOOKUP(V22,$F$10:$N$104,5,FALSE) -> 73
... E35: T11 | F35: Shane Lowry | G35: -1 | H35: -1 | I35: F | J35: 71 | K35: -- | L35: -- | M35: -- | N35: 71 | T35: 26 | U35: Jason Day | V35: Jason Day | W35: =+VLOOKUP(V35,$F$10:$N$104,5,FALSE) -> 70
E36: T27 | F36: Cameron Young | G36: E | H36: E | I36: F | J36: 72 | K36: -- | L36: -- | M36: -- | N36: 72 | T36: 27 | U36: Wyndham Clark | V36: Wyndham Clark | W36: =+VLOOKUP(V36,$F$10:$N$104,5,FALSE) -> 76
E37: T27 | F37: Zach Johnson | G37: E | H37: E | I37: F | J37: 72 | K37: -- | L37: -- | M37: -- | N37: 72 | T37: 28 | U37: Sepp Straka | V37: Sepp Straka | W37: =+VLOOKUP(V37,$F$10:$N$104,5,FALSE) -> 78
E38: T27 | F38: Stephan Jaeger | G38: E | H38: E | I38: F | J38: 72 | K38: -- | L38: -- | M38: -- | N38: 72 | T38: 29 | U38: Dustin Johnson | V38: Dustin Johnson | W38: =+VLOOKUP(V38,$F$10:$N$104,5,FALSE) -> 74
E39: T27 | F39: Collin Morikawa | G39: E | H39: E | I39: F | J39: 72 | K39: -- | L39: -- | M39: -- | N39: 72 | T39: 30 | U39: Sergio Garcia | V39: Sergio Garcia | W39: =+VLOOKUP(V39,$F$10:$N$104,5,FALSE) -> 72
E40: T27 | F40: Joaquín Niemann | G40: E | H40: E | I40: F | J40: 72 | K40: -- | L40: -- | M40: -- | N40: 72 | T40: 31 | U40: Patrick Reed | V40: Patrick Reed | W40: =+VLOOKUP(V40,$F$10:$N$104,5,FALSE) -> 71
E41: T27 | F41: Maverick McNealy | G41: E | H41: E | I41: F | J41: 72 | K41: -- | L41: -- | M41: -- | N41: 72 | T41: 32 | U41: Sahith Theegala | V41: Sahith Theegala | W41: =+VLOOKUP(V41,$F$10:$N$104,5,FALSE) -> 72
E42: T27 | F42: Brian Campbell | G42: E | H42: E | I42: F | J42: 72 | K42: -- | L42: -- | M42: -- | N42: 72 | T42: 33 | U42: Keegan Bradley | V42: Keegan Bradley | W42: =+VLOOKUP(V42,$F$10:$N$104,5,FALSE) -> 74
E43: T27 | F43: Tom Hoge | G43: E | H43: E | I43: F | J43: 72 | K43: -- | L43: -- | M43: -- | N43: 72 | T43: 34 | U43: Tom Kim | V43: Tom Kim | W43: =+VLOOKUP(V43,$F$10:$N$104,5,FALSE) -> 73
E44: T27 | F44: Sergio Garcia | G44: E | H44: E | I44: F | J44: 72 | K44: -- | L44: -- | M44: -- | N44: 72 | T44: 35 | U44: Justin Rose | V44: Justin Rose | W44: =+VLOOKUP(V44,$F$10:$N$104,5,FALSE) -> 65
E45: T27 | F45: Rory McIlroy | G45: E | H45: E | I45: F | J45: 72 | K45: -- | L45: -- | M45: -- | N45: 72 | T45: 36 | U45: Sungjae Im | V45: Sungjae Im | W45: =+VLOOKUP(V45,$F$10:$N$104,5,FALSE) -> 71
E46: T27 | F46: Sahith Theegala | G46: E | H46: E | I46: 17 | J46: 72 | K46: -- | L46: -- | M46: -- | N46: 68 | T46: 37 | U46: Daniel Berger | V46: Daniel Berger | W46: =+VLOOKUP(V46,$F$10:$N$104,5,FALSE) -> 71
E47: T38 | F47: Davis Riley | G47: 1 | H47: 1 | I47: F | J47: 73 | K47: -- | L47: -- | M47: -- | N47: 73 | T47: 38 | U47: Brian Harman | V47: Brian Harman | W47: =+VLOOKUP(V47,$F$10:$N$104,5,FALSE) -> 71
E48: T38 | F48: Nicolas Echavarria | G48: 1 | H48: 1 | I48: F | J48: 73 | K48: -- | L48: -- | M48: -- | N48: 73 | T48: 39 | U48: Matt Fitzpatrick | V48: Matt Fitzpatrick | W48: =+VLOOKUP(V48,$F$10:$N$104,5,FALSE) -> 71
E49: T38 | F49: Justin Thomas | G49: 1 | H49: 1 | I49: F | J49: 73 | K49: -- | L49: -- | M49: -- | N49: 73 | T49: 40 | U49: Adam Scott | V49: Adam Scott | W49: =+VLOOKUP(V49,$F$10:$N$104,5,FALSE) -> 77
E50: T38 | F50: Jordan Spieth | G50: 1 | H50: 1 | I50: F | J50: 73 | K50: -- | L50: -- | M50: -- | N50: 73 | T50: 41 | U50: J. J. Spaun | V50: J.J. Spaun | W50: =+VLOOKUP(V50,$F$10:$N$104,5,FALSE) -> 74
E51: T38 | F51: Tom Kim | G51: 1 | H51: 1 | I51: F | J51: 73 | K51: -- | L51: -- | M51: -- | N51: 73 | T51: 42 | U51: Sam Burns | V51: Sam Burns | W51: =+VLOOKUP(V51,$F$10:$N$104,5,FALSE) -> 73
E52: T38 | F52: Adam Schenk | G52: 1 | H52: 1 | I52: F | J52: 73 | K52: -- | L52: -- | M52: -- | N52: 73 | T52: 43 | U52: Davis Thompson | V52: Davis Thompson | W52: =+VLOOKUP(V52,$F$10:$N$104,5,FALSE) -> 71
E53: T38 | F53: Hiroshi Tai (a) | G53: 1 | H53: 1 | I53: F | J53: 73 | K53: -- | L53: -- | M53: -- | N53: 73 | T53: 44 | U53: Phil Mickelson | V53: Phil Mickelson | W53: =+VLOOKUP(V53,$F$10:$N$104,5,FALSE) -> 75
E54: T38 | F54: Nick Taylor | G54: 1 | H54: 1 | I54: F | J54: 73 | K54: -- | L54: -- | M54: -- | N54: 73 | T54: 45 | U54: Billy Horschel | V54: Billy Horschel | W54: =+VLOOKUP(V54,$F$10:$N$104,5,FALSE) -> 77
E55: T38 | F55: Rasmus Højgaard | G55: 1 | H55: 1 | I55: F | J55: 73 | K55: -- | L55: -- | M55: -- | N55: 73 | T55: 46 | U55: Taylor Pendrith | V55: Taylor Pendrith | W55: =+VLOOKUP(V55,$F$10:$N$104,5,FALSE) -> 77
E56: T38 | F56: Xander Schauffele | G56: 1 | H56: 1 | I56: F | J56: 73 | K56: -- | L56: -- | M56: -- | N56: 73 | T56: 47 | U56: Byeong Hun An | V56: Byeong Hun An | W56: =+VLOOKUP(V56,$F$10:$N$104,5,FALSE) -> 74
E57: T38 | F57: Hideki Matsuyama | G57: 1 | H57: 1 | I57: F | J57: 73 | K57: -- | L57: -- | M57: -- | N57: 73 | T57: 48 | U57: Aaron Rai | V57: Aaron Rai | W57: =+VLOOKUP(V57,$F$10:$N$104,5,FALSE) -> 70
E58: T38 | F58: Tommy Fleetwood | G58: 1 | H58: 1 | I58: F | J58: 73 | K58: -- | L58: -- | M58: -- | N58: 73 | T58: 49 | U58: Denny McCarthy | V58: Denny McCarthy | W58: =+VLOOKUP(V58,$F$10:$N$104,5,FALSE) -> 71
E59: T38 | F59: Sam Burns | G59: 1 | H59: 1 | I59: 17 | J59: 73 | K59: -- | L59: -- | M59: -- | N59: 69 | T59: 50 | U59: Maverick McNealy | V59: Maverick McNealy | W59: =+VLOOKUP(V59,$F$10:$N$104,5,FALSE) -> 72
E60: T51 | F60: Bernhard Langer | G60: 2 | H60: 2 | I60: F | J60: 74 | K60: -- | L60: -- | M60: -- | N60: 74 | T60: 51 | U60: Lucas Glover | V60: Lucas Glover | W60: =+VLOOKUP(V60,$F$10:$N$104,5,FALSE) -> 78
...
