Workbook

Sheet Rosters (FINAL)
A1: Team # | B1: Team | C1: Captain | D1: Initials | E1: Golfer 1 | F1: Golfer 2 | G1: Golfer 3 | H1: Golfer 4 | I1: Golfer 5 | J1: Golfer 6 | K1: Golfer 7 | L1: Golfer 8
A2: 1 | B2: Just when I thought I was out, they pull me back in | C2: Paul Castergine | D2: PC | E2: Ludvig Aberg | F2: Brooks Koepka | G2: Tommy Fleetwood | H2: Patrick Cantlay | I2: Sergio Garcia | J2: Sergio Garcia | K2: Jordan Spieth | L2: Cameron Young
A3: 2 | B3: Subpar Effort | C3: Nick Hooten | D3: NH | E3: Xander Schauffele | F3: Xander Schauffele | G3: Brooks Koepka | H3: Brooks Koepka | I3: Tony Finau | J3: Tony Finau | K3: Cameron Young | L3: Maverick McNealy
A4: 3 | B4: Minnesota Miracle | C4: Thad Williams | D4: TW | E4: Collin Morikawa | F4: Hideki Matsuyama | G4: Hideki Matsuyama | H4: Brooks Koepka | I4: Robert MacIntyre | J4: Will Zalatoris | K4: Phil Mickelson | L4: Laurie Canter
A5: 4 | B5: Play the fade | C5: Dan Riordan | D5: DR | E5: Ludvig Aberg | F5: Justin Thomas | G5: Hideki Matsuyama | H5: Russell Henley | I5: Akshay Bhatia | J5: Akshay Bhatia | K5: Corey Conners | L5: Lucas Glover
A6: 5 | B6: I Need A Pain Sponge | C6: Rob Schoen | D6: RS | E6: Justin Thomas | F6: Justin Thomas | G6: Shane Lowry | H6: Russell Henley | I6: Russell Henley | J6: Robert MacIntyre | K6: Min Woo Lee | L6: Will Zalatoris
A7: 6 | B7: Fire Nico | C7: Dan Lahrman | D7: DL | E7: Viktor Hovland | F7: Viktor Hovland | G7: Jordan Spieth | H7: Jordan Spieth | I7: Hideki Matsuyama | J7: Hideki Matsuyama | K7: Jason Day | L7: Jason Day
A8: 7 | B8: Gold Jacket, Green Jacket… | C8: Jon Schreiber | D8: JS | E8: Collin Morikawa | F8: Collin Morikawa | G8: Collin Morikawa | H8: Patrick Reed | I8: Maverick McNealy | J8: Cameron Young | K8: Stephan Jaeger | L8: Max Greyserman
A9: 8 | B9: LaPlant | C9: Matt LaPlant | D9: ML | E9: Xander Schauffele | F9: Xander Schauffele | G9: Bryson DeChambeau | H9: Shane Lowry | I9: Corey Conners | J9: Sepp Straka | K9: No Player | L9: No Player
A10: 9 | B10: Henley and the Double Eagles | C10: Adrian Chan | D10: AC | E10: Collin Morikawa | F10: Collin Morikawa | G10: Russell Henley | H10: Robert MacIntyre | I10: Robert MacIntyre | J10: Will Zalatoris | K10: Will Zalatoris | L10: No Player
A11: 10 | B11: The Long Irons | C11: Kathryn Michalewicz | D11: KM | E11: Rory McIlroy | F11: Tommy Fleetwood | G11: Viktor Hovland | H11: Min Woo Lee | I11: Matthieu Pavon | J11: No Player | K11: No Player | L11: No Player
A12: 11 | B12: Every day in Moving Day | C12: James Fetch | D12: JF | E12: Jon Rahm | F12: Bryson DeChambeau | G12: Brooks Koepka | H12: Jordan Spieth | I12: Patrick Reed | J12: Justin Rose | K12: Nicolai Højgaard | L12: Harris English
A13: 12 | B13: Lafferty, Daniel | C13: Brad McLaughlin | D13: BM | E13: Ludvig Aberg | F13: Collin Morikawa | G13: Viktor Hovland | H13: Bryson DeChambeau | I13: Tony Finau | J13: Nick Dunlap | K13: No Player | L13: No Player
... A40: 39 | B40: The Chipinskis | C40: Peter Sharpe | D40: PS | E40: Collin Morikawa | F40: Xander Schauffele | G40: Tom Hoge | H40: Tyrrell Hatton | I40: Min Woo Lee | J40: Shane Lowry | K40: Brian Harman | L40: Corey Conners

Sheet Round 1 Scores
A1: Team # | B1: Team | C1: Captain | D1: Initials | E1: Golfer 1 | G1: Golfer 2 | I1: Golfer 3 | K1: Golfer 4 | M1: Golfer 5 | O1: Golfer 6 | Q1: Golfer 7 | S1: Golfer 8 | U1: SCORE
A2: 1 | B2: Just when I thought I was out, they pull me back in | C2: Paul Castergine | D2: PC | E2: Ludvig Aberg | F2: =+VLOOKUP(E2,scoring!$U$10:$AA$105,3,FALSE)-72 -> -4 | G2: Brooks Koepka | H2: =+VLOOKUP(G2,scoring!$U$10:$AA$105,3,FALSE)-72 -> 2 | I2: Tommy Fleetwood | J2: =+VLOOKUP(I2,scoring!$U$10:$AA$105,3,FALSE)-72 -> 1 | K2: Patrick Cantlay | L2: =+VLOOKUP(K2,scoring!$U$10:$AA$105,3,FALSE)-72 -> 2 | M2: Sergio Garcia | N2: =+VLOOKUP(M2,scoring!$U$10:$AA$105,3,FALSE)-72 -> 0 | O2: Sergio Garcia | P2: =+VLOOKUP(O2,scoring!$U$10:$AA$105,3,FALSE)-72 -> 0 | Q2: Jordan Spieth | R2: =+VLOOKUP(Q2,scoring!$U$10:$AA$105,3,FALSE)-72 -> 1 | S2: Cameron Young | T2: =+VLOOKUP(S2,scoring!$U$10:$AA$105,3,FALSE)-72 -> 0 | U2: =IFERROR(SMALL(E2:T2,1)+SMALL(E2:T2,2)+SMALL(E2:T2,3),IFERROR(SMALL(E2:T2,1)+SMALL(E2:T2,2),IFERROR(SMALL(E2:T2,1),"-"))) -> -4
A3: 2 | B3: Subpar Effort | C3: Nick Hooten | D3: NH | E3: Xander Schauffele | F3: =+VLOOKUP(E3,scoring!$U$10:$AA$105,3,FALSE)-72 -> 1 | G3: Xander Schauffele | H3: =+VLOOKUP(G3,scoring!$U$10:$AA$105,3,FALSE)-72 -> 1 | I3: Brooks Koepka | J3: =+VLOOKUP(I3,scoring!$U$10:$AA$105,3,FALSE)-72 -> 2 | K3: Brooks Koepka | L3: =+VLOOKUP(K3,scoring!$U$10:$AA$105,3,FALSE)-72 -> 2 | M3: Tony Finau | N3: =+VLOOKUP(M3,scoring!$U$10:$AA$105,3,FALSE)-72 -> 3 | O3: Tony Finau | P3: =+VLOOKUP(O3,scoring!$U$10:$AA$105,3,FALSE)-72 -> 3 | Q3: Cameron Young | R3: =+VLOOKUP(Q3,scoring!$U$10:$AA$105,3,FALSE)-72 -> 0 | S3: Maverick McNealy | T3: =+VLOOKUP(S3,scoring!$U$10:$AA$105,3,FALSE)-72 -> 0 | U3: =IFERROR(SMALL(E3:T3,1)+SMALL(E3:T3,2)+SMALL(E3:T3,3),IFERROR(SMALL(E3:T3,1)+SMALL(E3:T3,2),IFERROR(SMALL(E3:T3,1),"-"))) -> 1
A4: 3 | B4: Minnesota Miracle | C4: Thad Williams | D4: TW | E4: Collin Morikawa | F4: =+VLOOKUP(E4,scoring!$U$10:$AA$105,3,FALSE)-72 -> 0 | G4: Hideki Matsuyama | H4: =+VLOOKUP(G4,scoring!$U$10:$AA$105,3,FALSE)-72 -> 1 | I4: Hideki Matsuyama | J4: =+VLOOKUP(I4,scoring!$U$10:$AA$105,3,FALSE)-72 -> 1 | K4: Brooks Koepka | L4: =+VLOOKUP(K4,scoring!$U$10:$AA$105,3,FALSE)-72 -> 2 | M4: Robert MacIntyre | N4: =+VLOOKUP(M4,scoring!$U$10:$AA$105,3,FALSE)-72 -> 3 | O4: Will Zalatoris | P4: =+VLOOKUP(O4,scoring!$U$10:$AA$105,3,FALSE)-72 -> 2 | Q4: Phil Mickelson | R4: =+VLOOKUP(Q4,scoring!$U$10:$AA$105,3,FALSE)-72 -> 3 | S4: Laurie Canter | T4: =+VLOOKUP(S4,scoring!$U$10:$AA$105,3,FALSE)-72 -> 5 | U4: =IFERROR(SMALL(E4:T4,1)+SMALL(E4:T4,2)+SMALL(E4:T4,3),IFERROR(SMALL(E4:T4,1)+SMALL(E4:T4,2),IFERROR(SMALL(E4:T4,1),"-"))) -> 2
A5: 4 | B5: Play the fade | C5: Dan Riordan | D5: DR | E5: Ludvig Aberg | F5: =+VLOOKUP(E5,scoring!$U$10:$AA$105,3,FALSE)-72 -> -4 | G5: Justin Thomas | H5: =+VLOOKUP(G5,scoring!$U$10:$AA$105,3,FALSE)-72 -> 1 | I5: Hideki Matsuyama | J5: =+VLOOKUP(I5,scoring!$U$10:$AA$105,3,FALSE)-72 -> 1 | K5: Russell Henley | L5: =+VLOOKUP(K5,scoring!$U$10:$AA$105,3,FALSE)-72 -> 7 | M5: Akshay Bhatia | N5: =+VLOOKUP(M5,scoring!$U$10:$AA$105,3,FALSE)-72 -> -2 | O5: Akshay Bhatia | P5: =+VLOOKUP(O5,scoring!$U$10:$AA$105,3,FALSE)-72 -> -2 | Q5: Corey Conners | R5: =+VLOOKUP(Q5,scoring!$U$10:$AA$105,3,FALSE)-72 -> -4 | S5: Lucas Glover | T5: =+VLOOKUP(S5,scoring!$U$10:$AA$105,3,FALSE)-72 -> 6 | U5: =IFERROR(SMALL(E5:T5,1)+SMALL(E5:T5,2)+SMALL(E5:T5,3),IFERROR(SMALL(E5:T5,1)+SMALL(E5:T5,2),IFERROR(SMALL(E5:T5,1),"-"))) -> -10
A6: 5 | B6: I Need A Pain Sponge | C6: Rob Schoen | D6: RS | E6: Justin Thomas | F6: =+VLOOKUP(E6,scoring!$U$10:$AA$105,3,FALSE)-72 -> 1 | G6: Justin Thomas | H6: =+VLOOKUP(G6,scoring!$U$10:$AA$105,3,FALSE)-72 -> 1 | I6: Shane Lowry | J6: =+VLOOKUP(I6,scoring!$U$10:$AA$105,3,FALSE)-72 -> -1 | K6: Russell Henley | L6: =+VLOOKUP(K6,scoring!$U$10:$AA$105,3,FALSE)-72 -> 7 | M6: Russell Henley | N6: =+VLOOKUP(M6,scoring!$U$10:$AA$105,3,FALSE)-72 -> 7 | O6: Robert MacIntyre | P6: =+VLOOKUP(O6,scoring!$U$10:$AA$105,3,FALSE)-72 -> 3 | Q6: Min Woo Lee | R6: =+VLOOKUP(Q6,scoring!$U$10:$AA$105,3,FALSE)-72 -> -1 | S6: Will Zalatoris | T6: =+VLOOKUP(S6,scoring!$U$10:$AA$105,3,FALSE)-72 -> 2 | U6: =IFERROR(SMALL(E6:T6,1)+SMALL(E6:T6,2)+SMALL(E6:T6,3),IFERROR(SMALL(E6:T6,1)+SMALL(E6:T6,2),IFERROR(SMALL(E6:T6,1),"-"))) -> -1
A7: 6 | B7: Fire Nico | C7: Dan Lahrman | D7: DL | E7: Viktor Hovland | F7: =+VLOOKUP(E7,scoring!$U$10:$AA$105,3,FALSE)-72 -> -1 | G7: Viktor Hovland | H7: =+VLOOKUP(G7,scoring!$U$10:$AA$105,3,FALSE)-72 -> -1 | I7: Jordan Spieth | J7: =+VLOOKUP(I7,scoring!$U$10:$AA$105,3,FALSE)-72 -> 1 | K7: Jordan Spieth | L7: =+VLOOKUP(K7,scoring!$U$10:$AA$105,3,FALSE)-72 -> 1 | M7: Hideki Matsuyama | N7: =+VLOOKUP(M7,scoring!$U$10:$AA$105,3,FALSE)-72 -> 1 | O7: Hideki Matsuyama | P7: =+VLOOKUP(O7,scoring!$U$10:$AA$105,3,FALSE)-72 -> 1 | Q7: Jason Day | R7: =+VLOOKUP(Q7,scoring!$U$10:$AA$105,3,FALSE)-72 -> -2 | S7: Jason Day | T7: =+VLOOKUP(S7,scoring!$U$10:$AA$105,3,FALSE)-72 -> -2 | U7: =IFERROR(SMALL(E7:T7,1)+SMALL(E7:T7,2)+SMALL(E7:T7,3),IFERROR(SMALL(E7:T7,1)+SMALL(E7:T7,2),IFERROR(SMALL(E7:T7,1),"-"))) -> -5
A8: 7 | B8: Gold Jacket, Green Jacket… | C8: Jon Schreiber | D8: JS | E8: Collin Morikawa | F8: =+VLOOKUP(E8,scoring!$U$10:$AA$105,3,FALSE)-72 -> 0 | G8: Collin Morikawa | H8: =+VLOOKUP(G8,scoring!$U$10:$AA$105,3,FALSE)-72 -> 0 | I8: Collin Morikawa | J8: =+VLOOKUP(I8,scoring!$U$10:$AA$105,3,FALSE)-72 -> 0 | K8: Patrick Reed | L8: =+VLOOKUP(K8,scoring!$U$10:$AA$105,3,FALSE)-72 -> -1 | M8: Maverick McNealy | N8: =+VLOOKUP(M8,scoring!$U$10:$AA$105,3,FALSE)-72 -> 0 | O8: Cameron Young | P8: =+VLOOKUP(O8,scoring!$U$10:$AA$105,3,FALSE)-72 -> 0 | Q8: Stephan Jaeger | R8: =+VLOOKUP(Q8,scoring!$U$10:$AA$105,3,FALSE)-72 -> 0 | S8: Max Greyserman | T8: =+VLOOKUP(S8,scoring!$U$10:$AA$105,3,FALSE)-72 -> -1 | U8: =IFERROR(SMALL(E8:T8,1)+SMALL(E8:T8,2)+SMALL(E8:T8,3),IFERROR(SMALL(E8:T8,1)+SMALL(E8:T8,2),IFERROR(SMALL(E8:T8,1),"-"))) -> -2
A9: 8 | B9: LaPlant | C9: Matt LaPlant | D9: ML | E9: Xander Schauffele | F9: =+VLOOKUP(E9,scoring!$U$10:$AA$105,3,FALSE)-72 -> 1 | G9: Xander Schauffele | H9: =+VLOOKUP(G9,scoring!$U$10:$AA$105,3,FALSE)-72 -> 1 | I9: Bryson DeChambeau | J9: =+VLOOKUP(I9,scoring!$U$10:$AA$105,3,FALSE)-72 -> -3 | K9: Shane Lowry | L9: =+VLOOKUP(K9,scoring!$U$10:$AA$105,3,FALSE)-72 -> -1 | M9: Corey Conners | N9: =+VLOOKUP(M9,scoring!$U$10:$AA$105,3,FALSE)-72 -> -4 | O9: Sepp Straka | P9: =+VLOOKUP(O9,scoring!$U$10:$AA$105,3,FALSE)-72 -> 6 | Q9: No Player | R9: =+VLOOKUP(Q9,scoring!$U$10:$AA$105,3,FALSE)-72 -> 19 | S9: No Player | T9: =+VLOOKUP(S9,scoring!$U$10:$AA$105,3,FALSE)-72 -> 19 | U9: =IFERROR(SMALL(E9:T9,1)+SMALL(E9:T9,2)+SMALL(E9:T9,3),IFERROR(SMALL(E9:T9,1)+SMALL(E9:T9,2),IFERROR(SMALL(E9:T9,1),"-"))) -> -8
A10: 9 | B10: Henley and the Double Eagles | C10: Adrian Chan | D10: AC | E10: Collin Morikawa | F10: =+VLOOKUP(E10,scoring!$U$10:$AA$105,3,FALSE)-72 -> 0 | G10: Collin Morikawa | H10: =+VLOOKUP(G10,scoring!$U$10:$AA$105,3,FALSE)-72 -> 0 | I10: Russell Henley | J10: =+VLOOKUP(I10,scoring!$U$10:$AA$105,3,FALSE)-72 -> 7 | K10: Robert MacIntyre | L10: =+VLOOKUP(K10,scoring!$U$10:$AA$105,3,FALSE)-72 -> 3 | M10: Robert MacIntyre | N10: =+VLOOKUP(M10,scoring!$U$10:$AA$105,3,FALSE)-72 -> 3 | O10: Will Zalatoris | P10: =+VLOOKUP(O10,scoring!$U$10:$AA$105,3,FALSE)-72 -> 2 | Q10: Will Zalatoris | R10: =+VLOOKUP(Q10,scoring!$U$10:$AA$105,3,FALSE)-72 -> 2 | S10: No Player | T10: =+VLOOKUP(S10,scoring!$U$10:$AA$105,3,FALSE)-72 -> 19 | U10: =IFERROR(SMALL(E10:T10,1)+SMALL(E10:T10,2)+SMALL(E10:T10,3),IFERROR(SMALL(E10:T10,1)+SMALL(E10:T10,2),IFERROR(SMALL(E10:T10,1),"-"))) -> 2
A11: 10 | B11: The Long Irons | C11: Kathryn Michalewicz | D11: KM | E11: Rory McIlroy | F11: =+VLOOKUP(E11,scoring!$U$10:$AA$105,3,FALSE)-72 -> 0 | G11: Tommy Fleetwood | H11: =+VLOOKUP(G11,scoring!$U$10:$AA$105,3,FALSE)-72 -> 1 | I11: Viktor Hovland | J11: =+VLOOKUP(I11,scoring!$U$10:$AA$105,3,FALSE)-72 -> -1 | K11: Min Woo Lee | L11: =+VLOOKUP(K11,scoring!$U$10:$AA$105,3,FALSE)-72 -> -1 | M11: Matthieu Pavon | N11: =+VLOOKUP(M11,scoring!$U$10:$AA$105,3,FALSE)-72 -> 6 | O11: No Player | P11: =+VLOOKUP(O11,scoring!$U$10:$AA$105,3,FALSE)-72 -> 19 | Q11: No Player | R11: =+VLOOKUP(Q11,scoring!$U$10:$AA$105,3,FALSE)-72 -> 19 | S11: No Player | T11: =+VLOOKUP(S11,scoring!$U$10:$AA$105,3,FALSE)-72 -> 19 | U11: =IFERROR(SMALL(E11:T11,1)+SMALL(E11:T11,2)+SMALL(E11:T11,3),IFERROR(SMALL(E11:T11,1)+SMALL(E11:T11,2),IFERROR(SMALL(E11:T11,1),"-"))) -> -2
A12: 11 | B12: Every day is Moving Day | C12: James Fetch | D12: JF | E12: Jon Rahm | F12: =+VLOOKUP(E12,scoring!$U$10:$AA$105,3,FALSE)-72 -> 3 | G12: Bryson DeChambeau | H12: =+VLOOKUP(G12,scoring!$U$10:$AA$105,3,FALSE)-72 -> -3 | I12: Brooks Koepka | J12: =+VLOOKUP(I12,scoring!$U$10:$AA$105,3,FALSE)-72 -> 2 | K12: Jordan Spieth | L12: =+VLOOKUP(K12,scoring!$U$10:$AA$105,3,FALSE)-72 -> 1 | M12: Patrick Reed | N12: =+VLOOKUP(M12,scoring!$U$10:$AA$105,3,FALSE)-72 -> -1 | O12: Justin Rose | P12: =+VLOOKUP(O12,scoring!$U$10:$AA$105,3,FALSE)-72 -> -7 | Q12: Nicolai Højgaard | R12: =+VLOOKUP(Q12,scoring!$U$10:$AA$105,3,FALSE)-72 -> 4 | S12: Harris English | T12: =+VLOOKUP(S12,scoring!$U$10:$AA$105,3,FALSE)-72 -> -2 | U12: =IFERROR(SMALL(E12:T12,1)+SMALL(E12:T12,2)+SMALL(E12:T12,3),IFERROR(SMALL(E12:T12,1)+SMALL(E12:T12,2),IFERROR(SMALL(E12:T12,1),"-"))) -> -12
A13: 12 | B13: Lafferty, Daniel | C13: Brad McLaughlin | D13: BM | E13: Ludvig Aberg | F13: =+VLOOKUP(E13,scoring!$U$10:$AA$105,3,FALSE)-72 -> -4 | G13: Collin Morikawa | H13: =+VLOOKUP(G13,scoring!$U$10:$AA$105,3,FALSE)-72 -> 0 | I13: Viktor Hovland | J13: =+VLOOKUP(I13,scoring!$U$10:$AA$105,3,FALSE)-72 -> -1 | K13: Bryson DeChambeau | L13: =+VLOOKUP(K13,scoring!$U$10:$AA$105,3,FALSE)-72 -> -3 | M13: Tony Finau | N13: =+VLOOKUP(M13,scoring!$U$10:$AA$105,3,FALSE)-72 -> 3 | O13: Nick Dunlap | P13: =+VLOOKUP(O13,scoring!$U$10:$AA$105,3,FALSE)-72 -> 18 | Q13: No Player | R13: =+VLOOKUP(Q13,scoring!$U$10:$AA$105,3,FALSE)-72 -> 19 | S13: No Player | T13: =+VLOOKUP(S13,scoring!$U$10:$AA$105,3,FALSE)-72 -> 19 | U13: =IFERROR(SMALL(E13:T13,1)+SMALL(E13:T13,2)+SMALL(E13:T13,3),IFERROR(SMALL(E13:T13,1)+SMALL(E13:T13,2),IFERROR(SMALL(E13:T13,1),"-"))) -> -8
... A40: 39 | B40: The Chipinskis | C40: Peter Sharpe | D40: PS | E40: Collin Morikawa | F40: =+VLOOKUP(E40,scoring!$U$10:$AA$105,3,FALSE)-72 -> 0 | G40: Xander Schauffele | H40: =+VLOOKUP(G40,scoring!$U$10:$AA$105,3,FALSE)-72 -> 1 | I40: Tom Hoge | J40: =+VLOOKUP(I40,scoring!$U$10:$AA$105,3,FALSE)-72 -> 0 | K40: Tyrrell Hatton | L40: =+VLOOKUP(K40,scoring!$U$10:$AA$105,3,FALSE)-72 -> -3 | M40: Min Woo Lee | N40: =+VLOOKUP(M40,scoring!$U$10:$AA$105,3,FALSE)-72 -> -1 | O40: Shane Lowry | P40: =+VLOOKUP(O40,scoring!$U$10:$AA$105,3,FALSE)-72 -> -1 | Q40: Brian Harman | R40: =+VLOOKUP(Q40,scoring!$U$10:$AA$105,3,FALSE)-72 -> -1 | S40: Corey Conners | T40: =+VLOOKUP(S40,scoring!$U$10:$AA$105,3,FALSE)-72 -> -4 | U40: =IFERROR(SMALL(E40:T40,1)+SMALL(E40:T40,2)+SMALL(E40:T40,3),IFERROR(SMALL(E40:T40,1)+SMALL(E40:T40,2),IFERROR(SMALL(E40:T40,1),"-"))) -> -8
U42: =+MAX(U2:U40) -> 2

Sheet Round 2 Scores
A1: Round 2
A2: Team # | B2: Team | C2: Captain | D2: Initials | E2: Golfer 1 | G2: Golfer 2 | I2: Golfer 3 | K2: Golfer 4 | M2: Golfer 5 | O2: Golfer 6 | Q2: Golfer 7 | S2: Golfer 8 | U2: SCORE
A3: 1 | B3: Just when I thought I was out, they pull me back in | C3: Paul Castergine | D3: PC | E3: Ludvig Aberg | F3: =+VLOOKUP(E3,scoring!$U$10:$AA$105,4,FALSE)-72 -> 1 | G3: Brooks Koepka | H3: =+VLOOKUP(G3,scoring!$U$10:$AA$105,4,FALSE)-72 -> 3 | I3: Tommy Fleetwood | J3: =+VLOOKUP(I3,scoring!$U$10:$AA$105,4,FALSE)-72 -> -3 | K3: Patrick Cantlay | L3: =+VLOOKUP(K3,scoring!$U$10:$AA$105,4,FALSE)-72 -> 0 | M3: Sergio Garcia | N3: =+VLOOKUP(M3,scoring!$U$10:$AA$105,4,FALSE)-72 -> 4 | O3: Sergio Garcia | P3: =+VLOOKUP(O3,scoring!$U$10:$AA$105,4,FALSE)-72 -> 4 | Q3: Jordan Spieth | R3: =+VLOOKUP(Q3,scoring!$U$10:$AA$105,4,FALSE)-72 -> 1 | S3: Cameron Young | T3: =+VLOOKUP(S3,scoring!$U$10:$AA$105,4,FALSE)-72 -> 7 | U3: =IFERROR(SMALL(E3:T3,1)+SMALL(E3:T3,2)+SMALL(E3:T3,3),IFERROR(SMALL(E3:T3,1)+SMALL(E3:T3,2),IFERROR(SMALL(E3:T3,1),"-"))) -> -2
A4: 2 | B4: Subpar Effort | C4: Nick Hooten | D4: NH | E4: Xander Schauffele | F4: =+VLOOKUP(E4,scoring!$U$10:$AA$105,4,FALSE)-72 -> -3 | G4: Xander Schauffele | H4: =+VLOOKUP(G4,scoring!$U$10:$AA$105,4,FALSE)-72 -> -3 | I4: Brooks Koepka | J4: =+VLOOKUP(I4,scoring!$U$10:$AA$105,4,FALSE)-72 -> 3 | K4: Brooks Koepka | L4: =+VLOOKUP(K4,scoring!$U$10:$AA$105,4,FALSE)-72 -> 3 | M4: Tony Finau | N4: =+VLOOKUP(M4,scoring!$U$10:$AA$105,4,FALSE)-72 -> 1 | O4: Tony Finau | P4: =+VLOOKUP(O4,scoring!$U$10:$AA$105,4,FALSE)-72 -> 1 | Q4: Cameron Young | R4: =+VLOOKUP(Q4,scoring!$U$10:$AA$105,4,FALSE)-72 -> 7 | S4: Maverick McNealy | T4: =+VLOOKUP(S4,scoring!$U$10:$AA$105,4,FALSE)-72 -> 1 | U4: =IFERROR(SMALL(E4:T4,1)+SMALL(E4:T4,2)+SMALL(E4:T4,3),IFERROR(SMALL(E4:T4,1)+SMALL(E4:T4,2),IFERROR(SMALL(E4:T4,1),"-"))) -> -5
A5: 3 | B5: Minnesota Miracle | C5: Thad Williams | D5: TW | E5: Collin Morikawa | F5: =+VLOOKUP(E5,scoring!$U$10:$AA$105,4,FALSE)-72 -> -3 | G5: Hideki Matsuyama | H5: =+VLOOKUP(G5,scoring!$U$10:$AA$105,4,FALSE)-72 -> -4 | I5: Hideki Matsuyama | J5: =+VLOOKUP(I5,scoring!$U$10:$AA$105,4,FALSE)-72 -> -4 | K5: Brooks Koepka | L5: =+VLOOKUP(K5,scoring!$U$10:$AA$105,4,FALSE)-72 -> 3 | M5: Robert MacIntyre | N5: =+VLOOKUP(M5,scoring!$U$10:$AA$105,4,FALSE)-72 -> 3 | O5: Will Zalatoris | P5: =+VLOOKUP(O5,scoring!$U$10:$AA$105,4,FALSE)-72 -> 6 | Q5: Phil Mickelson | R5: =+VLOOKUP(Q5,scoring!$U$10:$AA$105,4,FALSE)-72 -> 2 | S5: Laurie Canter | T5: =+VLOOKUP(S5,scoring!$U$10:$AA$105,4,FALSE)-72 -> 5 | U5: =IFERROR(SMALL(E5:T5,1)+SMALL(E5:T5,2)+SMALL(E5:T5,3),IFERROR(SMALL(E5:T5,1)+SMALL(E5:T5,2),IFERROR(SMALL(E5:T5,1),"-"))) -> -11
A6: 4 | B6: Play the fade | C6: Dan Riordan | D6: DR | E6: Ludvig Aberg | F6: =+VLOOKUP(E6,scoring!$U$10:$AA$105,4,FALSE)-72 -> 1 | G6: Justin Thomas | H6: =+VLOOKUP(G6,scoring!$U$10:$AA$105,4,FALSE)-72 -> -1 | I6: Hideki Matsuyama | J6: =+VLOOKUP(I6,scoring!$U$10:$AA$105,4,FALSE)-72 -> -4 | K6: Russell Henley | L6: =+VLOOKUP(K6,scoring!$U$10:$AA$105,4,FALSE)-72 -> -4 | M6: Akshay Bhatia | N6: =+VLOOKUP(M6,scoring!$U$10:$AA$105,4,FALSE)-72 -> 4 | O6: Akshay Bhatia | P6: =+VLOOKUP(O6,scoring!$U$10:$AA$105,4,FALSE)-72 -> 4 | Q6: Corey Conners | R6: =+VLOOKUP(Q6,scoring!$U$10:$AA$105,4,FALSE)-72 -> -2 | S6: Lucas Glover | T6: =+VLOOKUP(S6,scoring!$U$10:$AA$105,4,FALSE)-72 -> 2 | U6: =IFERROR(SMALL(E6:T6,1)+SMALL(E6:T6,2)+SMALL(E6:T6,3),IFERROR(SMALL(E6:T6,1)+SMALL(E6:T6,2),IFERROR(SMALL(E6:T6,1),"-"))) -> -10
A7: 5 | B7: I Need A Pain Sponge | C7: Rob Schoen | D7: RS | E7: Justin Thomas | F7: =+VLOOKUP(E7,scoring!$U$10:$AA$105,4,FALSE)-72 -> -1 | G7: Justin Thomas | H7: =+VLOOKUP(G7,scoring!$U$10:$AA$105,4,FALSE)-72 -> -1 | I7: Shane Lowry | J7: =+VLOOKUP(I7,scoring!$U$10:$AA$105,4,FALSE)-72 -> -4 | K7: Russell Henley | L7: =+VLOOKUP(K7,scoring!$U$10:$AA$105,4,FALSE)-72 -> -4 | M7: Russell Henley | N7: =+VLOOKUP(M7,scoring!$U$10:$AA$105,4,FALSE)-72 -> -4 | O7: Robert MacIntyre | P7: =+VLOOKUP(O7,scoring!$U$10:$AA$105,4,FALSE)-72 -> 3 | Q7: Min Woo Lee | R7: =+VLOOKUP(Q7,scoring!$U$10:$AA$105,4,FALSE)-72 -> 0 | S7: Will Zalatoris | T7: =+VLOOKUP(S7,scoring!$U$10:$AA$105,4,FALSE)-72 -> 6 | U7: =IFERROR(SMALL(E7:T7,1)+SMALL(E7:T7,2)+SMALL(E7:T7,3),IFERROR(SMALL(E7:T7,1)+SMALL(E7:T7,2),IFERROR(SMALL(E7:T7,1),"-"))) -> -12
A8: 6 | B8: Fire Nico | C8: Dan Lahrman | D8: DL | E8: Viktor Hovland | F8: =+VLOOKUP(E8,scoring!$U$10:$AA$105,4,FALSE)-72 -> -3 | G8: Viktor Hovland | H8: =+VLOOKUP(G8,scoring!$U$10:$AA$105,4,FALSE)-72 -> -3 | I8: Jordan Spieth | J8: =+VLOOKUP(I8,scoring!$U$10:$AA$105,4,FALSE)-72 -> 1 | K8: Jordan Spieth | L8: =+VLOOKUP(K8,scoring!$U$10:$AA$105,4,FALSE)-72 -> 1 | M8: Hideki Matsuyama | N8: =+VLOOKUP(M8,scoring!$U$10:$AA$105,4,FALSE)-72 -> -4 | O8: Hideki Matsuyama | P8: =+VLOOKUP(O8,scoring!$U$10:$AA$105,4,FALSE)-72 -> -4 | Q8: Jason Day | R8: =+VLOOKUP(Q8,scoring!$U$10:$AA$105,4,FALSE)-72 -> -2 | S8: Jason Day | T8: =+VLOOKUP(S8,scoring!$U$10:$AA$105,4,FALSE)-72 -> -2 | U8: =IFERROR(SMALL(E8:T8,1)+SMALL(E8:T8,2)+SMALL(E8:T8,3),IFERROR(SMALL(E8:T8,1)+SMALL(E8:T8,2),IFERROR(SMALL(E8:T8,1),"-"))) -> -11
A9: 7 | B9: Gold Jacket, Green Jacket… | C9: Jon Schreiber | D9: JS | E9: Collin Morikawa | F9: =+VLOOKUP(E9,scoring!$U$10:$AA$105,4,FALSE)-72 -> -3 | G9: Collin Morikawa | H9: =+VLOOKUP(G9,scoring!$U$10:$AA$105,4,FALSE)-72 -> -3 | I9: Collin Morikawa | J9: =+VLOOKUP(I9,scoring!$U$10:$AA$105,4,FALSE)-72 -> -3 | K9: Patrick Reed | L9: =+VLOOKUP(K9,scoring!$U$10:$AA$105,4,FALSE)-72 -> -2 | M9: Maverick McNealy | N9: =+VLOOKUP(M9,scoring!$U$10:$AA$105,4,FALSE)-72 -> 1 | O9: Cameron Young | P9: =+VLOOKUP(O9,scoring!$U$10:$AA$105,4,FALSE)-72 -> 7 | Q9: Stephan Jaeger | R9: =+VLOOKUP(Q9,scoring!$U$10:$AA$105,4,FALSE)-72 -> 2 | S9: Max Greyserman | T9: =+VLOOKUP(S9,scoring!$U$10:$AA$105,4,FALSE)-72 -> 3 | U9: =IFERROR(SMALL(E9:T9,1)+SMALL(E9:T9,2)+SMALL(E9:T9,3),IFERROR(SMALL(E9:T9,1)+SMALL(E9:T9,2),IFERROR(SMALL(E9:T9,1),"-"))) -> -9
A10: 8 | B10: LaPlant | C10: Matt LaPlant | D10: ML | E10: Xander Schauffele | F10: =+VLOOKUP(E10,scoring!$U$10:$AA$105,4,FALSE)-72 -> -3 | G10: Xander Schauffele | H10: =+VLOOKUP(G10,scoring!$U$10:$AA$105,4,FALSE)-72 -> -3 | I10: Bryson DeChambeau | J10: =+VLOOKUP(I10,scoring!$U$10:$AA$105,4,FALSE)-72 -> -4 | K10: Shane Lowry | L10: =+VLOOKUP(K10,scoring!$U$10:$AA$105,4,FALSE)-72 -> -4 | M10: Corey Conners | N10: =+VLOOKUP(M10,scoring!$U$10:$AA$105,4,FALSE)-72 -> -2 | O10: Sepp Straka | P10: =+VLOOKUP(O10,scoring!$U$10:$AA$105,4,FALSE)-72 -> -1 | Q10: No Player | R10: =+VLOOKUP(Q10,scoring!$U$10:$AA$105,4,FALSE)-72 -> 9 | S10: No Player | T10: =+VLOOKUP(S10,scoring!$U$10:$AA$105,4,FALSE)-72 -> 9 | U10: =IFERROR(SMALL(E10:T10,1)+SMALL(E10:T10,2)+SMALL(E10:T10,3),IFERROR(SMALL(E10:T10,1)+SMALL(E10:T10,2),IFERROR(SMALL(E10:T10,1),"-"))) -> -11
A11: 9 | B11: Henley and the Double Eagles | C11: Adrian Chan | D11: AC | E11: Collin Morikawa | F11: =+VLOOKUP(E11,scoring!$U$10:$AA$105,4,FALSE)-72 -> -3 | G11: Collin Morikawa | H11: =+VLOOKUP(G11,scoring!$U$10:$AA$105,4,FALSE)-72 -> -3 | I11: Russell Henley | J11: =+VLOOKUP(I11,scoring!$U$10:$AA$105,4,FALSE)-72 -> -4 | K11: Robert MacIntyre | L11: =+VLOOKUP(K11,scoring!$U$10:$AA$105,4,FALSE)-72 -> 3 | M11: Robert MacIntyre | N11: =+VLOOKUP(M11,scoring!$U$10:$AA$105,4,FALSE)-72 -> 3 | O11: Will Zalatoris | P11: =+VLOOKUP(O11,scoring!$U$10:$AA$105,4,FALSE)-72 -> 6 | Q11: Will Zalatoris | R11: =+VLOOKUP(Q11,scoring!$U$10:$AA$105,4,FALSE)-72 -> 6 | S11: No Player | T11: =+VLOOKUP(S11,scoring!$U$10:$AA$105,4,FALSE)-72 -> 9 | U11: =IFERROR(SMALL(E11:T11,1)+SMALL(E11:T11,2)+SMALL(E11:T11,3),IFERROR(SMALL(E11:T11,1)+SMALL(E11:T11,2),IFERROR(SMALL(E11:T11,1),"-"))) -> -10
A12: 10 | B12: The Long Irons | C12: Kathryn Michalewicz | D12: KM | E12: Rory McIlroy | F12: =+VLOOKUP(E12,scoring!$U$10:$AA$105,4,FALSE)-72 -> -6 | G12: Tommy Fleetwood | H12: =+VLOOKUP(G12,scoring!$U$10:$AA$105,4,FALSE)-72 -> -3 | I12: Viktor Hovland | J12: =+VLOOKUP(I12,scoring!$U$10:$AA$105,4,FALSE)-72 -> -3 | K12: Min Woo Lee | L12: =+VLOOKUP(K12,scoring!$U$10:$AA$105,4,FALSE)-72 -> 0 | M12: Matthieu Pavon | N12: =+VLOOKUP(M12,scoring!$U$10:$AA$105,4,FALSE)-72 -> 4 | O12: No Player | P12: =+VLOOKUP(O12,scoring!$U$10:$AA$105,4,FALSE)-72 -> 9 | Q12: No Player | R12: =+VLOOKUP(Q12,scoring!$U$10:$AA$105,4,FALSE)-72 -> 9 | S12: No Player | T12: =+VLOOKUP(S12,scoring!$U$10:$AA$105,4,FALSE)-72 -> 9 | U12: =IFERROR(SMALL(E12:T12,1)+SMALL(E12:T12,2)+SMALL(E12:T12,3),IFERROR(SMALL(E12:T12,1)+SMALL(E12:T12,2),IFERROR(SMALL(E12:T12,1),"-"))) -> -12
A13: 11 | B13: Every day is Moving Day | C13: James Fetch | D13: JF | E13: Jon Rahm | F13: =+VLOOKUP(E13,scoring!$U$10:$AA$105,4,FALSE)-72 -> -1 | G13: Bryson DeChambeau | H13: =+VLOOKUP(G13,scoring!$U$10:$AA$105,4,FALSE)-72 -> -4 | I13: Brooks Koepka | J13: =+VLOOKUP(I13,scoring!$U$10:$AA$105,4,FALSE)-72 -> 3 | K13: Jordan Spieth | L13: =+VLOOKUP(K13,scoring!$U$10:$AA$105,4,FALSE)-72 -> 1 | M13: Patrick Reed | N13: =+VLOOKUP(M13,scoring!$U$10:$AA$105,4,FALSE)-72 -> -2 | O13: Justin Rose | P13: =+VLOOKUP(O13,scoring!$U$10:$AA$105,4,FALSE)-72 -> -1 | Q13: Nicolai Højgaard | R13: =+VLOOKUP(Q13,scoring!$U$10:$AA$105,4,FALSE)-72 -> 2 | S13: Harris English | T13: =+VLOOKUP(S13,scoring!$U$10:$AA$105,4,FALSE)-72 -> 1 | U13: =IFERROR(SMALL(E13:T13,1)+SMALL(E13:T13,2)+SMALL(E13:T13,3),IFERROR(SMALL(E13:T13,1)+SMALL(E13:T13,2),IFERROR(SMALL(E13:T13,1),"-"))) -> -7
A14: 12 | B14: Lafferty, Daniel | C14: Brad McLaughlin | D14: BM | E14: Ludvig Aberg | F14: =+VLOOKUP(E14,scoring!$U$10:$AA$105,4,FALSE)-72 -> 1 | G14: Collin Morikawa | H14: =+VLOOKUP(G14,scoring!$U$10:$AA$105,4,FALSE)-72 -> -3 | I14: Viktor Hovland | J14: =+VLOOKUP(I14,scoring!$U$10:$AA$105,4,FALSE)-72 -> -3 | K14: Bryson DeChambeau | L14: =+VLOOKUP(K14,scoring!$U$10:$AA$105,4,FALSE)-72 -> -4 | M14: Tony Finau | N14: =+VLOOKUP(M14,scoring!$U$10:$AA$105,4,FALSE)-72 -> 1 | O14: Nick Dunlap | P14: =+VLOOKUP(O14,scoring!$U$10:$AA$105,4,FALSE)-72 -> -1 | Q14: No Player | R14: =+VLOOKUP(Q14,scoring!$U$10:$AA$105,4,FALSE)-72 -> 9 | S14: No Player | T14: =+VLOOKUP(S14,scoring!$U$10:$AA$105,4,FALSE)-72 -> 9 | U14: =IFERROR(SMALL(E14:T14,1)+SMALL(E14:T14,2)+SMALL(E14:T14,3),IFERROR(SMALL(E14:T14,1)+SMALL(E14:T14,2),IFERROR(SMALL(E14:T14,1),"-"))) -> -10
... A41: 39 | B41: The Chipinskis | C41: Peter Sharpe | D41: PS | E41: Collin Morikawa | F41: =+VLOOKUP(E41,scoring!$U$10:$AA$105,4,FALSE)-72 -> -3 | G41: Xander Schauffele | H41: =+VLOOKUP(G41,scoring!$U$10:$AA$105,4,FALSE)-72 -> -3 | I41: Tom Hoge | J41: =+VLOOKUP(I41,scoring!$U$10:$AA$105,4,FALSE)-72 -> 0 | K41: Tyrrell Hatton | L41: =+VLOOKUP(K41,scoring!$U$10:$AA$105,4,FALSE)-72 -> -2 | M41: Min Woo Lee | N41: =+VLOOKUP(M41,scoring!$U$10:$AA$105,4,FALSE)-72 -> 0 | O41: Shane Lowry | P41: =+VLOOKUP(O41,scoring!$U$10:$AA$105,4,FALSE)-72 -> -4 | Q41: Brian Harman | R41: =+VLOOKUP(Q41,scoring!$U$10:$AA$105,4,FALSE)-72 -> -1 | S41: Corey Conners | T41: =+VLOOKUP(S41,scoring!$U$10:$AA$105,4,FALSE)-72 -> -2 | U41: =IFERROR(SMALL(E41:T41,1)+SMALL(E41:T41,2)+SMALL(E41:T41,3),IFERROR(SMALL(E41:T41,1)+SMALL(E41:T41,2),IFERROR(SMALL(E41:T41,1),"-"))) -> -10

Sheet Round 3 Scores
A1: Round 3
A2: Team # | B2: Team | C2: Captain | D2: Initials | E2: Golfer 1 | G2: Golfer 2 | I2: Golfer 3 | K2: Golfer 4 | M2: Golfer 5 | O2: Golfer 6 | Q2: Golfer 7 | S2: Golfer 8 | U2: SCORE
A3: 36 | B3: Often wrong but never in doubt | C3: Scott Sipple | D3: SS | E3: Rory McIlroy | F3: =+VLOOKUP(E3,scoring!$U$10:$AA$105,5,FALSE)-72 -> -6 | G3: Ludvig Aberg | H3: =+VLOOKUP(G3,scoring!$U$10:$AA$105,5,FALSE)-72 -> -3 | I3: Daniel Berger | J3: =+VLOOKUP(I3,scoring!$U$10:$AA$105,5,FALSE)-72 -> 1 | K3: Maverick McNealy | L3: =+VLOOKUP(K3,scoring!$U$10:$AA$105,5,FALSE)-72 -> -1 | M3: No Player | N3: =+VLOOKUP(M3,scoring!$U$10:$AA$105,5,FALSE)-72 -> 9 | O3: No Player | P3: =+VLOOKUP(O3,scoring!$U$10:$AA$105,5,FALSE)-72 -> 9 | Q3: No Player | R3: =+VLOOKUP(Q3,scoring!$U$10:$AA$105,5,FALSE)-72 -> 9 | S3: No Player | T3: =+VLOOKUP(S3,scoring!$U$10:$AA$105,5,FALSE)-72 -> 9 | U3: =IFERROR(SMALL(E3:T3,1)+SMALL(E3:T3,2)+SMALL(E3:T3,3),IFERROR(SMALL(E3:T3,1)+SMALL(E3:T3,2),IFERROR(SMALL(E3:T3,1),"-"))) -> -10
A4: 11 | B4: Every day is Moving Day | C4: James Fetch | D4: JF | E4: Jon Rahm | F4: =+VLOOKUP(E4,scoring!$U$10:$AA$105,5,FALSE)-72 -> -2 | G4: Bryson DeChambeau | H4: =+VLOOKUP(G4,scoring!$U$10:$AA$105,5,FALSE)-72 -> -3 | I4: Brooks Koepka | J4: =+VLOOKUP(I4,scoring!$U$10:$AA$105,5,FALSE)-72 -> 8 | K4: Jordan Spieth | L4: =+VLOOKUP(K4,scoring!$U$10:$AA$105,5,FALSE)-72 -> -3 | M4: Patrick Reed | N4: =+VLOOKUP(M4,scoring!$U$10:$AA$105,5,FALSE)-72 -> -3 | O4: Justin Rose | P4: =+VLOOKUP(O4,scoring!$U$10:$AA$105,5,FALSE)-72 -> 3 | Q4: Nicolai Højgaard | R4: =+VLOOKUP(Q4,scoring!$U$10:$AA$105,5,FALSE)-72 -> 8 | S4: Harris English | T4: =+VLOOKUP(S4,scoring!$U$10:$AA$105,5,FALSE)-72 -> 1 | U4: =IFERROR(SMALL(E4:T4,1)+SMALL(E4:T4,2)+SMALL(E4:T4,3),IFERROR(SMALL(E4:T4,1)+SMALL(E4:T4,2),IFERROR(SMALL(E4:T4,1),"-"))) -> -9
A5: 15 | B5: Ludvig Levered 2x Daily | C5: Jacob Norris | D5: JN | E5: Ludvig Aberg | F5: =+VLOOKUP(E5,scoring!$U$10:$AA$105,5,FALSE)-72 -> -3 | G5: Ludvig Aberg | H5: =+VLOOKUP(G5,scoring!$U$10:$AA$105,5,FALSE)-72 -> -3 | I5: Russell Henley | J5: =+VLOOKUP(I5,scoring!$U$10:$AA$105,5,FALSE)-72 -> 8 | K5: Russell Henley | L5: =+VLOOKUP(K5,scoring!$U$10:$AA$105,5,FALSE)-72 -> 8 | M5: Viktor Hovland | N5: =+VLOOKUP(M5,scoring!$U$10:$AA$105,5,FALSE)-72 -> 1 | O5: Patrick Reed | P5: =+VLOOKUP(O5,scoring!$U$10:$AA$105,5,FALSE)-72 -> -3 | Q5: Lucas Glover | R5: =+VLOOKUP(Q5,scoring!$U$10:$AA$105,5,FALSE)-72 -> 8 | S5: Lucas Glover | T5: =+VLOOKUP(S5,scoring!$U$10:$AA$105,5,FALSE)-72 -> 8 | U5: =IFERROR(SMALL(E5:T5,1)+SMALL(E5:T5,2)+SMALL(E5:T5,3),IFERROR(SMALL(E5:T5,1)+SMALL(E5:T5,2),IFERROR(SMALL(E5:T5,1),"-"))) -> -9
A6: 23 | B6: TheProperLuncher | C6: Charles Ouellett | D6: CO | E6: Ludvig Aberg | F6: =+VLOOKUP(E6,scoring!$U$10:$AA$105,5,FALSE)-72 -> -3 | G6: Ludvig Aberg | H6: =+VLOOKUP(G6,scoring!$U$10:$AA$105,5,FALSE)-72 -> -3 | I6: Ludvig Aberg | J6: =+VLOOKUP(I6,scoring!$U$10:$AA$105,5,FALSE)-72 -> -3 | K6: Cameron Smith | L6: =+VLOOKUP(K6,scoring!$U$10:$AA$105,5,FALSE)-72 -> 8 | M6: Corey Conners | N6: =+VLOOKUP(M6,scoring!$U$10:$AA$105,5,FALSE)-72 -> -2 | O6: No Player | P6: =+VLOOKUP(O6,scoring!$U$10:$AA$105,5,FALSE)-72 -> 9 | Q6: No Player | R6: =+VLOOKUP(Q6,scoring!$U$10:$AA$105,5,FALSE)-72 -> 9 | S6: No Player | T6: =+VLOOKUP(S6,scoring!$U$10:$AA$105,5,FALSE)-72 -> 9 | U6: =IFERROR(SMALL(E6:T6,1)+SMALL(E6:T6,2)+SMALL(E6:T6,3),IFERROR(SMALL(E6:T6,1)+SMALL(E6:T6,2),IFERROR(SMALL(E6:T6,1),"-"))) -> -9
A7: 30 | B7: Dilly Dilly | C7: Kim Arney | D7: KA | E7: Keegan Bradley | F7: =+VLOOKUP(E7,scoring!$U$10:$AA$105,5,FALSE)-72 -> 8 | G7: Zach Johnson | H7: =+VLOOKUP(G7,scoring!$U$10:$AA$105,5,FALSE)-72 -> -6 | I7: Shane Lowry | J7: =+VLOOKUP(I7,scoring!$U$10:$AA$105,5,FALSE)-72 -> 0 | K7: Viktor Hovland | L7: =+VLOOKUP(K7,scoring!$U$10:$AA$105,5,FALSE)-72 -> 1 | M7: Viktor Hovland | N7: =+VLOOKUP(M7,scoring!$U$10:$AA$105,5,FALSE)-72 -> 1 | O7: Sepp Straka | P7: =+VLOOKUP(O7,scoring!$U$10:$AA$105,5,FALSE)-72 -> 8 | Q7: Ludvig Aberg | R7: =+VLOOKUP(Q7,scoring!$U$10:$AA$105,5,FALSE)-72 -> -3 | S7: Justin Thomas | T7: =+VLOOKUP(S7,scoring!$U$10:$AA$105,5,FALSE)-72 -> 4 | U7: =IFERROR(SMALL(E7:T7,1)+SMALL(E7:T7,2)+SMALL(E7:T7,3),IFERROR(SMALL(E7:T7,1)+SMALL(E7:T7,2),IFERROR(SMALL(E7:T7,1),"-"))) -> -9
A8: 33 | B8: Ty Webb's illegitimate stepchild | C8: Tom Nelson | D8: TN | E8: Ludvig Aberg | F8: =+VLOOKUP(E8,scoring!$U$10:$AA$105,5,FALSE)-72 -> -3 | G8: Ludvig Aberg | H8: =+VLOOKUP(G8,scoring!$U$10:$AA$105,5,FALSE)-72 -> -3 | I8: Justin Rose | J8: =+VLOOKUP(I8,scoring!$U$10:$AA$105,5,FALSE)-72 -> 3 | K8: Patrick Reed | L8: =+VLOOKUP(K8,scoring!$U$10:$AA$105,5,FALSE)-72 -> -3 | M8: Justin Thomas | N8: =+VLOOKUP(M8,scoring!$U$10:$AA$105,5,FALSE)-72 -> 4 | O8: J. J. Spaun | P8: =+VLOOKUP(O8,scoring!$U$10:$AA$105,5,FALSE)-72 -> 2 | Q8: Bubba Watson | R8: =+VLOOKUP(Q8,scoring!$U$10:$AA$105,5,FALSE)-72 -> 2 | S8: Tony Finau | T8: =+VLOOKUP(S8,scoring!$U$10:$AA$105,5,FALSE)-72 -> 8 | U8: =IFERROR(SMALL(E8:T8,1)+SMALL(E8:T8,2)+SMALL(E8:T8,3),IFERROR(SMALL(E8:T8,1)+SMALL(E8:T8,2),IFERROR(SMALL(E8:T8,1),"-"))) -> -9
A9: 38 | B9: Green Machine | C9: Laura Green | D9: LG | E9: Ludvig Aberg | F9: =+VLOOKUP(E9,scoring!$U$10:$AA$105,5,FALSE)-72 -> -3 | G9: Ludvig Aberg | H9: =+VLOOKUP(G9,scoring!$U$10:$AA$105,5,FALSE)-72 -> -3 | I9: Bryson DeChambeau | J9: =+VLOOKUP(I9,scoring!$U$10:$AA$105,5,FALSE)-72 -> -3 | K9: Min Woo Lee | L9: =+VLOOKUP(K9,scoring!$U$10:$AA$105,5,FALSE)-72 -> 5 | M9: Sahith Theegala | N9: =+VLOOKUP(M9,scoring!$U$10:$AA$105,5,FALSE)-72 -> 1 | O9: Billy Horschel | P9: =+VLOOKUP(O9,scoring!$U$10:$AA$105,5,FALSE)-72 -> 8 | Q9: Cameron Young | R9: =+VLOOKUP(Q9,scoring!$U$10:$AA$105,5,FALSE)-72 -> 8 | S9: Jhonattan Vegas | T9: =+VLOOKUP(S9,scoring!$U$10:$AA$105,5,FALSE)-72 -> 8 | U9: =IFERROR(SMALL(E9:T9,1)+SMALL(E9:T9,2)+SMALL(E9:T9,3),IFERROR(SMALL(E9:T9,1)+SMALL(E9:T9,2),IFERROR(SMALL(E9:T9,1),"-"))) -> -9
A10: 29 | B10: MullinsDoubles | C10: Andy Mullins | D10: AM | E10: Bryson DeChambeau | F10: =+VLOOKUP(E10,scoring!$U$10:$AA$105,5,FALSE)-72 -> -3 | G10: Bryson DeChambeau | H10: =+VLOOKUP(G10,scoring!$U$10:$AA$105,5,FALSE)-72 -> -3 | I10: Joaquin Niemann | J10: =+VLOOKUP(I10,scoring!$U$10:$AA$105,5,FALSE)-72 -> -2 | K10: Joaquin Niemann | L10: =+VLOOKUP(K10,scoring!$U$10:$AA$105,5,FALSE)-72 -> -2 | M10: Robert MacIntyre | N10: =+VLOOKUP(M10,scoring!$U$10:$AA$105,5,FALSE)-72 -> 8 | O10: Robert MacIntyre | P10: =+VLOOKUP(O10,scoring!$U$10:$AA$105,5,FALSE)-72 -> 8 | Q10: No Player | R10: =+VLOOKUP(Q10,scoring!$U$10:$AA$105,5,FALSE)-72 -> 9 | S10: No Player | T10: =+VLOOKUP(S10,scoring!$U$10:$AA$105,5,FALSE)-72 -> 9 | U10: =IFERROR(SMALL(E10:T10,1)+SMALL(E10:T10,2)+SMALL(E10:T10,3),IFERROR(SMALL(E10:T10,1)+SMALL(E10:T10,2),IFERROR(SMALL(E10:T10,1),"-"))) -> -8
A11: 6 | B11: Fire Nico | C11: Dan Lahrman | D11: DL | E11: Viktor Hovland | F11: =+VLOOKUP(E11,scoring!$U$10:$AA$105,5,FALSE)-72 -> 1 | G11: Viktor Hovland | H11: =+VLOOKUP(G11,scoring!$U$10:$AA$105,5,FALSE)-72 -> 1 | I11: Jordan Spieth | J11: =+VLOOKUP(I11,scoring!$U$10:$AA$105,5,FALSE)-72 -> -3 | K11: Jordan Spieth | L11: =+VLOOKUP(K11,scoring!$U$10:$AA$105,5,FALSE)-72 -> -3 | M11: Hideki Matsuyama | N11: =+VLOOKUP(M11,scoring!$U$10:$AA$105,5,FALSE)-72 -> 7 | O11: Hideki Matsuyama | P11: =+VLOOKUP(O11,scoring!$U$10:$AA$105,5,FALSE)-72 -> 7 | Q11: Jason Day | R11: =+VLOOKUP(Q11,scoring!$U$10:$AA$105,5,FALSE)-72 -> -1 | S11: Jason Day | T11: =+VLOOKUP(S11,scoring!$U$10:$AA$105,5,FALSE)-72 -> -1 | U11: =IFERROR(SMALL(E11:T11,1)+SMALL(E11:T11,2)+SMALL(E11:T11,3),IFERROR(SMALL(E11:T11,1)+SMALL(E11:T11,2),IFERROR(SMALL(E11:T11,1),"-"))) -> -7
A12: 7 | B12: Gold Jacket, Green Jacket… | C12: Jon Schreiber | D12: JS | E12: Collin Morikawa | F12: =+VLOOKUP(E12,scoring!$U$10:$AA$105,5,FALSE)-72 -> 0 | G12: Collin Morikawa | H12: =+VLOOKUP(G12,scoring!$U$10:$AA$105,5,FALSE)-72 -> 0 | I12: Collin Morikawa | J12: =+VLOOKUP(I12,scoring!$U$10:$AA$105,5,FALSE)-72 -> 0 | K12: Patrick Reed | L12: =+VLOOKUP(K12,scoring!$U$10:$AA$105,5,FALSE)-72 -> -3 | M12: Maverick McNealy | N12: =+VLOOKUP(M12,scoring!$U$10:$AA$105,5,FALSE)-72 -> -1 | O12: Cameron Young | P12: =+VLOOKUP(O12,scoring!$U$10:$AA$105,5,FALSE)-72 -> 8 | Q12: Stephan Jaeger | R12: =+VLOOKUP(Q12,scoring!$U$10:$AA$105,5,FALSE)-72 -> 1 | S12: Max Greyserman | T12: =+VLOOKUP(S12,scoring!$U$10:$AA$105,5,FALSE)-72 -> -3 | U12: =IFERROR(SMALL(E12:T12,1)+SMALL(E12:T12,2)+SMALL(E12:T12,3),IFERROR(SMALL(E12:T12,1)+SMALL(E12:T12,2),IFERROR(SMALL(E12:T12,1),"-"))) -> -7
A13: 8 | B13: LaPlant | C13: Matt LaPlant | D13: ML | E13: Xander Schauffele | F13: =+VLOOKUP(E13,scoring!$U$10:$AA$105,5,FALSE)-72 -> -2 | G13: Xander Schauffele | H13: =+VLOOKUP(G13,scoring!$U$10:$AA$105,5,FALSE)-72 -> -2 | I13: Bryson DeChambeau | J13: =+VLOOKUP(I13,scoring!$U$10:$AA$105,5,FALSE)-72 -> -3 | K13: Shane Lowry | L13: =+VLOOKUP(K13,scoring!$U$10:$AA$105,5,FALSE)-72 -> 0 | M13: Corey Conners | N13: =+VLOOKUP(M13,scoring!$U$10:$AA$105,5,FALSE)-72 -> -2 | O13: Sepp Straka | P13: =+VLOOKUP(O13,scoring!$U$10:$AA$105,5,FALSE)-72 -> 8 | Q13: No Player | R13: =+VLOOKUP(Q13,scoring!$U$10:$AA$105,5,FALSE)-72 -> 9 | S13: No Player | T13: =+VLOOKUP(S13,scoring!$U$10:$AA$105,5,FALSE)-72 -> 9 | U13: =IFERROR(SMALL(E13:T13,1)+SMALL(E13:T13,2)+SMALL(E13:T13,3),IFERROR(SMALL(E13:T13,1)+SMALL(E13:T13,2),IFERROR(SMALL(E13:T13,1),"-"))) -> -7
A14: 35 | B14: The Nemeinators | C14: Ryan Nemes | D14: RN | E14: Joaquin Niemann | F14: =+VLOOKUP(E14,scoring!$U$10:$AA$105,5,FALSE)-72 -> -2 | G14: Joaquin Niemann | H14: =+VLOOKUP(G14,scoring!$U$10:$AA$105,5,FALSE)-72 -> -2 | I14: Collin Morikawa | J14: =+VLOOKUP(I14,scoring!$U$10:$AA$105,5,FALSE)-72 -> 0 | K14: Collin Morikawa | L14: =+VLOOKUP(K14,scoring!$U$10:$AA$105,5,FALSE)-72 -> 0 | M14: Min Woo Lee | N14: =+VLOOKUP(M14,scoring!$U$10:$AA$105,5,FALSE)-72 -> 5 | O14: Max Homa | P14: =+VLOOKUP(O14,scoring!$U$10:$AA$105,5,FALSE)-72 -> -3 | Q14: No Player | R14: =+VLOOKUP(Q14,scoring!$U$10:$AA$105,5,FALSE)-72 -> 9 | S14: No Player | T14: =+VLOOKUP(S14,scoring!$U$10:$AA$105,5,FALSE)-72 -> 9 | U14: =IFERROR(SMALL(E14:T14,1)+SMALL(E14:T14,2)+SMALL(E14:T14,3),IFERROR(SMALL(E14:T14,1)+SMALL(E14:T14,2),IFERROR(SMALL(E14:T14,1),"-"))) -> -7
... A41: 3 | B41: Minnesota Miracle | C41: Thad Williams | D41: TW | E41: Collin Morikawa | F41: =+VLOOKUP(E41,scoring!$U$10:$AA$105,5,FALSE)-72 -> 0 | G41: Hideki Matsuyama | H41: =+VLOOKUP(G41,scoring!$U$10:$AA$105,5,FALSE)-72 -> 7 | I41: Hideki Matsuyama | J41: =+VLOOKUP(I41,scoring!$U$10:$AA$105,5,FALSE)-72 -> 7 | K41: Brooks Koepka | L41: =+VLOOKUP(K41,scoring!$U$10:$AA$105,5,FALSE)-72 -> 8 | M41: Robert MacIntyre | N41: =+VLOOKUP(M41,scoring!$U$10:$AA$105,5,FALSE)-72 -> 8 | O41: Will Zalatoris | P41: =+VLOOKUP(O41,scoring!$U$10:$AA$105,5,FALSE)-72 -> 8 | Q41: Phil Mickelson | R41: =+VLOOKUP(Q41,scoring!$U$10:$AA$105,5,FALSE)-72 -> 8 | S41: Laurie Canter | T41: =+VLOOKUP(S41,scoring!$U$10:$AA$105,5,FALSE)-72 -> 8 | U41: =IFERROR(SMALL(E41:T41,1)+SMALL(E41:T41,2)+SMALL(E41:T41,3),IFERROR(SMALL(E41:T41,1)+SMALL(E41:T41,2),IFERROR(SMALL(E41:T41,1),"-"))) -> 14
A44: Total through 3 rounds
A45: Team # | B45: Team | C45: Captain | D45: Initials | E45: Golfer 1 | G45: Golfer 2 | I45: Golfer 3 | K45: Golfer 4 | M45: Golfer 5 | O45: Golfer 6 | Q45: Golfer 7 | S45: Golfer 8 | U45: SCORE
A46: 8 | B46: LaPlant | C46: Matt LaPlant | D46: ML | E46: Xander Schauffele | F46: =+VLOOKUP(E46,scoring!$U$10:$AA$105,7,FALSE)-72*3 -> 67 | G46: Xander Schauffele | H46: =+VLOOKUP(G46,scoring!$U$10:$AA$105,7,FALSE)-72*3 -> 67 | I46: Bryson DeChambeau | J46: =+VLOOKUP(I46,scoring!$U$10:$AA$105,7,FALSE)-72*3 -> 65 | K46: Shane Lowry | L46: =+VLOOKUP(K46,scoring!$U$10:$AA$105,7,FALSE)-72*3 -> 76 | M46: Corey Conners | N46: =+VLOOKUP(M46,scoring!$U$10:$AA$105,7,FALSE)-72*3 -> 67 | O46: Sepp Straka | P46: =+VLOOKUP(O46,scoring!$U$10:$AA$105,7,FALSE)-72*3 -> 98 | Q46: No Player | R46: =+VLOOKUP(Q46,scoring!$U$10:$AA$105,7,FALSE)-72*3 -> 111 | S46: No Player | T46: =+VLOOKUP(S46,scoring!$U$10:$AA$105,7,FALSE)-72*3 -> 111 | U46: =IFERROR(SMALL(E46:T46,1)+SMALL(E46:T46,2)+SMALL(E46:T46,3),IFERROR(SMALL(E46:T46,1)+SMALL(E46:T46,2),IFERROR(SMALL(E46:T46,1),"-"))) -> 199
A47: 38 | B47: Green Machine | C47: Laura Green | D47: LG | E47: Ludvig Aberg | F47: =+VLOOKUP(E47,scoring!$U$10:$AA$105,7,FALSE)-72*3 -> 66 | G47: Ludvig Aberg | H47: =+VLOOKUP(G47,scoring!$U$10:$AA$105,7,FALSE)-72*3 -> 66 | I47: Bryson DeChambeau | J47: =+VLOOKUP(I47,scoring!$U$10:$AA$105,7,FALSE)-72*3 -> 65 | K47: Min Woo Lee | L47: =+VLOOKUP(K47,scoring!$U$10:$AA$105,7,FALSE)-72*3 -> 78 | M47: Sahith Theegala | N47: =+VLOOKUP(M47,scoring!$U$10:$AA$105,7,FALSE)-72*3 -> 72 | O47: Billy Horschel | P47: =+VLOOKUP(O47,scoring!$U$10:$AA$105,7,FALSE)-72*3 -> 98 | Q47: Cameron Young | R47: =+VLOOKUP(Q47,scoring!$U$10:$AA$105,7,FALSE)-72*3 -> 100 | S47: Jhonattan Vegas | T47: =+VLOOKUP(S47,scoring!$U$10:$AA$105,7,FALSE)-72*3 -> 99 | U47: =IFERROR(SMALL(E47:T47,1)+SMALL(E47:T47,2)+SMALL(E47:T47,3),IFERROR(SMALL(E47:T47,1)+SMALL(E47:T47,2),IFERROR(SMALL(E47:T47,1),"-"))) -> 197
A48: 11 | B48: Every day is Moving Day | C48: James Fetch | D48: JF | E48: Jon Rahm | F48: =+VLOOKUP(E48,scoring!$U$10:$AA$105,7,FALSE)-72*3 -> 69 | G48: Bryson DeChambeau | H48: =+VLOOKUP(G48,scoring!$U$10:$AA$105,7,FALSE)-72*3 -> 65 | I48: Brooks Koepka | J48: =+VLOOKUP(I48,scoring!$U$10:$AA$105,7,FALSE)-72*3 -> 98 | K48: Jordan Spieth | L48: =+VLOOKUP(K48,scoring!$U$10:$AA$105,7,FALSE)-72*3 -> 69 | M48: Patrick Reed | N48: =+VLOOKUP(M48,scoring!$U$10:$AA$105,7,FALSE)-72*3 -> 63 | O48: Justin Rose | P48: =+VLOOKUP(O48,scoring!$U$10:$AA$105,7,FALSE)-72*3 -> 61 | Q48: Nicolai Højgaard | R48: =+VLOOKUP(Q48,scoring!$U$10:$AA$105,7,FALSE)-72*3 -> 99 | S48: Harris English | T48: =+VLOOKUP(S48,scoring!$U$10:$AA$105,7,FALSE)-72*3 -> 68 | U48: =IFERROR(SMALL(E48:T48,1)+SMALL(E48:T48,2)+SMALL(E48:T48,3),IFERROR(SMALL(E48:T48,1)+SMALL(E48:T48,2),IFERROR(SMALL(E48:T48,1),"-"))) -> 189
A49: 23 | B49: TheProperLuncher | C49: Charles Ouellett | D49: CO | E49: Ludvig Aberg | F49: =+VLOOKUP(E49,scoring!$U$10:$AA$105,7,FALSE)-72*3 -> 66 | G49: Ludvig Aberg | H49: =+VLOOKUP(G49,scoring!$U$10:$AA$105,7,FALSE)-72*3 -> 66 | I49: Ludvig Aberg | J49: =+VLOOKUP(I49,scoring!$U$10:$AA$105,7,FALSE)-72*3 -> 66 | K49: Cameron Smith | L49: =+VLOOKUP(K49,scoring!$U$10:$AA$105,7,FALSE)-72*3 -> 98 | M49: Corey Conners | N49: =+VLOOKUP(M49,scoring!$U$10:$AA$105,7,FALSE)-72*3 -> 67 | O49: No Player | P49: =+VLOOKUP(O49,scoring!$U$10:$AA$105,7,FALSE)-72*3 -> 111 | Q49: No Player | R49: =+VLOOKUP(Q49,scoring!$U$10:$AA$105,7,FALSE)-72*3 -> 111 | S49: No Player | T49: =+VLOOKUP(S49,scoring!$U$10:$AA$105,7,FALSE)-72*3 -> 111 | U49: =IFERROR(SMALL(E49:T49,1)+SMALL(E49:T49,2)+SMALL(E49:T49,3),IFERROR(SMALL(E49:T49,1)+SMALL(E49:T49,2),IFERROR(SMALL(E49:T49,1),"-"))) -> 198
A50: 29 | B50: MullinsDoubles | C50: Andy Mullins | D50: AM | E50: Bryson DeChambeau | F50: =+VLOOKUP(E50,scoring!$U$10:$AA$105,7,FALSE)-72*3 -> 65 | G50: Bryson DeChambeau | H50: =+VLOOKUP(G50,scoring!$U$10:$AA$105,7,FALSE)-72*3 -> 65 | I50: Joaquin Niemann | J50: =+VLOOKUP(I50,scoring!$U$10:$AA$105,7,FALSE)-72*3 -> 72 | K50: Joaquin Niemann | L50: =+VLOOKUP(K50,scoring!$U$10:$AA$105,7,FALSE)-72*3 -> 72 | M50: Robert MacIntyre | N50: =+VLOOKUP(M50,scoring!$U$10:$AA$105,7,FALSE)-72*3 -> 99 | O50: Robert MacIntyre | P50: =+VLOOKUP(O50,scoring!$U$10:$AA$105,7,FALSE)-72*3 -> 99 | Q50: No Player | R50: =+VLOOKUP(Q50,scoring!$U$10:$AA$105,7,FALSE)-72*3 -> 111 | S50: No Player | T50: =+VLOOKUP(S50,scoring!$U$10:$AA$105,7,FALSE)-72*3 -> 111 | U50: =IFERROR(SMALL(E50:T50,1)+SMALL(E50:T50,2)+SMALL(E50:T50,3),IFERROR(SMALL(E50:T50,1)+SMALL(E50:T50,2),IFERROR(SMALL(E50:T50,1),"-"))) -> 202
A51: 12 | B51: Lafferty, Daniel | C51: Brad McLaughlin | D51: BM | E51: Ludvig Aberg | F51: =+VLOOKUP(E51,scoring!$U$10:$AA$105,7,FALSE)-72*3 -> 66 | G51: Collin Morikawa | H51: =+VLOOKUP(G51,scoring!$U$10:$AA$105,7,FALSE)-72*3 -> 69 | I51: Viktor Hovland | J51: =+VLOOKUP(I51,scoring!$U$10:$AA$105,7,FALSE)-72*3 -> 70 | K51: Bryson DeChambeau | L51: =+VLOOKUP(K51,scoring!$U$10:$AA$105,7,FALSE)-72*3 -> 65 | M51: Tony Finau | N51: =+VLOOKUP(M51,scoring!$U$10:$AA$105,7,FALSE)-72*3 -> 97 | O51: Nick Dunlap | P51: =+VLOOKUP(O51,scoring!$U$10:$AA$105,7,FALSE)-72*3 -> 110 | Q51: No Player | R51: =+VLOOKUP(Q51,scoring!$U$10:$AA$105,7,FALSE)-72*3 -> 111 | S51: No Player | T51: =+VLOOKUP(S51,scoring!$U$10:$AA$105,7,FALSE)-72*3 -> 111 | U51: =IFERROR(SMALL(E51:T51,1)+SMALL(E51:T51,2)+SMALL(E51:T51,3),IFERROR(SMALL(E51:T51,1)+SMALL(E51:T51,2),IFERROR(SMALL(E51:T51,1),"-"))) -> 200
A52: 18 | B52: Kangaroo Took My Ball | C52: Chris Floyd | D52: CF | E52: Collin Morikawa | F52: =+VLOOKUP(E52,scoring!$U$10:$AA$105,7,FALSE)-72*3 -> 69 | G52: Bryson DeChambeau | H52: =+VLOOKUP(G52,scoring!$U$10:$AA$105,7,FALSE)-72*3 -> 65 | I52: Xander Schauffele | J52: =+VLOOKUP(I52,scoring!$U$10:$AA$105,7,FALSE)-72*3 -> 67 | K52: Shane Lowry | L52: =+VLOOKUP(K52,scoring!$U$10:$AA$105,7,FALSE)-72*3 -> 76 | M52: Will Zalatoris | N52: =+VLOOKUP(M52,scoring!$U$10:$AA$105,7,FALSE)-72*3 -> 101 | O52: Nick Taylor | P52: =+VLOOKUP(O52,scoring!$U$10:$AA$105,7,FALSE)-72*3 -> 75 | Q52: No Player | R52: =+VLOOKUP(Q52,scoring!$U$10:$AA$105,7,FALSE)-72*3 -> 111 | S52: No Player | T52: =+VLOOKUP(S52,scoring!$U$10:$AA$105,7,FALSE)-72*3 -> 111 | U52: =IFERROR(SMALL(E52:T52,1)+SMALL(E52:T52,2)+SMALL(E52:T52,3),IFERROR(SMALL(E52:T52,1)+SMALL(E52:T52,2),IFERROR(SMALL(E52:T52,1),"-"))) -> 201
A53: 15 | B53: Ludvig Levered 2x Daily | C53: Jacob Norris | D53: JN | E53: Ludvig Aberg | F53: =+VLOOKUP(E53,scoring!$U$10:$AA$105,7,FALSE)-72*3 -> 66 | G53: Ludvig Aberg | H53: =+VLOOKUP(G53,scoring!$U$10:$AA$105,7,FALSE)-72*3 -> 66 | I53: Russell Henley | J53: =+VLOOKUP(I53,scoring!$U$10:$AA$105,7,FALSE)-72*3 -> 96 | K53: Russell Henley | L53: =+VLOOKUP(K53,scoring!$U$10:$AA$105,7,FALSE)-72*3 -> 96 | M53: Viktor Hovland | N53: =+VLOOKUP(M53,scoring!$U$10:$AA$105,7,FALSE)-72*3 -> 70 | O53: Patrick Reed | P53: =+VLOOKUP(O53,scoring!$U$10:$AA$105,7,FALSE)-72*3 -> 63 | Q53: Lucas Glover | R53: =+VLOOKUP(Q53,scoring!$U$10:$AA$105,7,FALSE)-72*3 -> 101 | S53: Lucas Glover | T53: =+VLOOKUP(S53,scoring!$U$10:$AA$105,7,FALSE)-72*3 -> 101 | U53: =IFERROR(SMALL(E53:T53,1)+SMALL(E53:T53,2)+SMALL(E53:T53,3),IFERROR(SMALL(E53:T53,1)+SMALL(E53:T53,2),IFERROR(SMALL(E53:T53,1),"-"))) -> 195
A54: 22 | B54: Scattershot | C54: Bill Kohli | D54: BK | E54: Collin Morikawa | F54: =+VLOOKUP(E54,scoring!$U$10:$AA$105,7,FALSE)-72*3 -> 69 | G54: Hideki Matsuyama | H54: =+VLOOKUP(G54,scoring!$U$10:$AA$105,7,FALSE)-72*3 -> 70 | I54: Shane Lowry | J54: =+VLOOKUP(I54,scoring!$U$10:$AA$105,7,FALSE)-72*3 -> 76 | K54: Patrick Cantlay | L54: =+VLOOKUP(K54,scoring!$U$10:$AA$105,7,FALSE)-72*3 -> 74 | M54: Min Woo Lee | N54: =+VLOOKUP(M54,scoring!$U$10:$AA$105,7,FALSE)-72*3 -> 78 | O54: Corey Conners | P54: =+VLOOKUP(O54,scoring!$U$10:$AA$105,7,FALSE)-72*3 -> 67 | Q54: Tony Finau | R54: =+VLOOKUP(Q54,scoring!$U$10:$AA$105,7,FALSE)-72*3 -> 97 | S54: Jason Day | T54: =+VLOOKUP(S54,scoring!$U$10:$AA$105,7,FALSE)-72*3 -> 67 | U54: =IFERROR(SMALL(E54:T54,1)+SMALL(E54:T54,2)+SMALL(E54:T54,3),IFERROR(SMALL(E54:T54,1)+SMALL(E54:T54,2),IFERROR(SMALL(E54:T54,1),"-"))) -> 203
A55: 33 | B55: Ty Webb's illegitimate stepchild | C55: Tom Nelson | D55: TN | E55: Ludvig Aberg | F55: =+VLOOKUP(E55,scoring!$U$10:$AA$105,7,FALSE)-72*3 -> 66 | G55: Ludvig Aberg | H55: =+VLOOKUP(G55,scoring!$U$10:$AA$105,7,FALSE)-72*3 -> 66 | I55: Justin Rose | J55: =+VLOOKUP(I55,scoring!$U$10:$AA$105,7,FALSE)-72*3 -> 61 | K55: Patrick Reed | L55: =+VLOOKUP(K55,scoring!$U$10:$AA$105,7,FALSE)-72*3 -> 63 | M55: Justin Thomas | N55: =+VLOOKUP(M55,scoring!$U$10:$AA$105,7,FALSE)-72*3 -> 74 | O55: J. J. Spaun | P55: =+VLOOKUP(O55,scoring!$U$10:$AA$105,7,FALSE)-72*3 -> 79 | Q55: Bubba Watson | R55: =+VLOOKUP(Q55,scoring!$U$10:$AA$105,7,FALSE)-72*3 -> 69 | S55: Tony Finau | T55: =+VLOOKUP(S55,scoring!$U$10:$AA$105,7,FALSE)-72*3 -> 97 | U55: =IFERROR(SMALL(E55:T55,1)+SMALL(E55:T55,2)+SMALL(E55:T55,3),IFERROR(SMALL(E55:T55,1)+SMALL(E55:T55,2),IFERROR(SMALL(E55:T55,1),"-"))) -> 190
A56: 36 | B56: Often wrong but never in doubt | C56: Scott Sipple | D56: SS | E56: Rory McIlroy | F56: =+VLOOKUP(E56,scoring!$U$10:$AA$105,7,FALSE)-72*3 -> 61 | G56: Ludvig Aberg | H56: =+VLOOKUP(G56,scoring!$U$10:$AA$105,7,FALSE)-72*3 -> 66 | I56: Daniel Berger | J56: =+VLOOKUP(I56,scoring!$U$10:$AA$105,7,FALSE)-72*3 -> 70 | K56: Maverick McNealy | L56: =+VLOOKUP(K56,scoring!$U$10:$AA$105,7,FALSE)-72*3 -> 73 | M56: No Player | N56: =+VLOOKUP(M56,scoring!$U$10:$AA$105,7,FALSE)-72*3 -> 111 | O56: No Player | P56: =+VLOOKUP(O56,scoring!$U$10:$AA$105,7,FALSE)-72*3 -> 111 | Q56: No Player | R56: =+VLOOKUP(Q56,scoring!$U$10:$AA$105,7,FALSE)-72*3 -> 111 | S56: No Player | T56: =+VLOOKUP(S56,scoring!$U$10:$AA$105,7,FALSE)-72*3 -> 111 | U56: =IFERROR(SMALL(E56:T56,1)+SMALL(E56:T56,2)+SMALL(E56:T56,3),IFERROR(SMALL(E56:T56,1)+SMALL(E56:T56,2),IFERROR(SMALL(E56:T56,1),"-"))) -> 197
A57: 39 | B57: The Chipinskis | C57: Peter Sharpe | D57: PS | E57: Collin Morikawa | F57: =+VLOOKUP(E57,scoring!$U$10:$AA$105,7,FALSE)-72*3 -> 69 | G57: Xander Schauffele | H57: =+VLOOKUP(G57,scoring!$U$10:$AA$105,7,FALSE)-72*3 -> 67 | I57: Tom Hoge | J57: =+VLOOKUP(I57,scoring!$U$10:$AA$105,7,FALSE)-72*3 -> 69 | K57: Tyrrell Hatton | L57: =+VLOOKUP(K57,scoring!$U$10:$AA$105,7,FALSE)-72*3 -> 69 | M57: Min Woo Lee | N57: =+VLOOKUP(M57,scoring!$U$10:$AA$105,7,FALSE)-72*3 -> 78 | O57: Shane Lowry | P57: =+VLOOKUP(O57,scoring!$U$10:$AA$105,7,FALSE)-72*3 -> 76 | Q57: Brian Harman | R57: =+VLOOKUP(Q57,scoring!$U$10:$AA$105,7,FALSE)-72*3 -> 74 | S57: Corey Conners | T57: =+VLOOKUP(S57,scoring!$U$10:$AA$105,7,FALSE)-72*3 -> 67 | U57: =IFERROR(SMALL(E57:T57,1)+SMALL(E57:T57,2)+SMALL(E57:T57,3),IFERROR(SMALL(E57:T57,1)+SMALL(E57:T57,2),IFERROR(SMALL(E57:T57,1),"-"))) -> 203
... A84: 14 | B84: District Five | C84: Tucker Donahoe | D84: TD | E84: Ludvig Aberg | F84: =+VLOOKUP(E84,scoring!$U$10:$AA$105,7,FALSE)-72*3 -> 66 | G84: Russell Henley | H84: =+VLOOKUP(G84,scoring!$U$10:$AA$105,7,FALSE)-72*3 -> 96 | I84: Russell Henley | J84: =+VLOOKUP(I84,scoring!$U$10:$AA$105,7,FALSE)-72*3 -> 96 | K84: Russell Henley | L84: =+VLOOKUP(K84,scoring!$U$10:$AA$105,7,FALSE)-72*3 -> 96 | M84: Cameron Smith | N84: =+VLOOKUP(M84,scoring!$U$10:$AA$105,7,FALSE)-72*3 -> 98 | O84: Cameron Smith | P84: =+VLOOKUP(O84,scoring!$U$10:$AA$105,7,FALSE)-72*3 -> 98 | Q84: Cameron Smith | R84: =+VLOOKUP(Q84,scoring!$U$10:$AA$105,7,FALSE)-72*3 -> 98 | S84: Brooks Koepka | T84: =+VLOOKUP(S84,scoring!$U$10:$AA$105,7,FALSE)-72*3 -> 98 | U84: =IFERROR(SMALL(E84:T84,1)+SMALL(E84:T84,2)+SMALL(E84:T84,3),IFERROR(SMALL(E84:T84,1)+SMALL(E84:T84,2),IFERROR(SMALL(E84:T84,1),"-"))) -> 258
B86: LaPlant | C86: Matt LaPlant | D86: ML | E86: Xander Schauffele | F86: =+VLOOKUP(E86,scoring!$U$10:$AA$105,7,FALSE)-72*3 -> 67 | G86: Xander Schauffele | H86: =+VLOOKUP(G86,scoring!$U$10:$AA$105,7,FALSE)-72*3 -> 67 | I86: Bryson DeChambeau | J86: =+VLOOKUP(I86,scoring!$U$10:$AA$105,7,FALSE)-72*3 -> 65 | K86: Shane Lowry | L86: =+VLOOKUP(K86,scoring!$U$10:$AA$105,7,FALSE)-72*3 -> 76 | M86: Corey Conners | N86: =+VLOOKUP(M86,scoring!$U$10:$AA$105,7,FALSE)-72*3 -> 67 | O86: Sepp Straka | P86: =+VLOOKUP(O86,scoring!$U$10:$AA$105,7,FALSE)-72*3 -> 98 | Q86: No Player | R86: =+VLOOKUP(Q86,scoring!$U$10:$AA$105,7,FALSE)-72*3 -> 111 | S86: No Player | T86: =+VLOOKUP(S86,scoring!$U$10:$AA$105,7,FALSE)-72*3 -> 111 | U86: =IFERROR(SMALL(E86:T86,1)+SMALL(E86:T86,2)+SMALL(E86:T86,3),IFERROR(SMALL(E86:T86,1)+SMALL(E86:T86,2),IFERROR(SMALL(E86:T86,1),"-"))) -> 199
B87: Green Machine | C87: Laura Green | D87: LG | E87: Ludvig Aberg | F87: =+VLOOKUP(E87,scoring!$U$10:$AA$105,7,FALSE)-72*3 -> 66 | G87: Ludvig Aberg | H87: =+VLOOKUP(G87,scoring!$U$10:$AA$105,7,FALSE)-72*3 -> 66 | I87: Bryson DeChambeau | J87: =+VLOOKUP(I87,scoring!$U$10:$AA$105,7,FALSE)-72*3 -> 65 | K87: Min Woo Lee | L87: =+VLOOKUP(K87,scoring!$U$10:$AA$105,7,FALSE)-72*3 -> 78 | M87: Sahith Theegala | N87: =+VLOOKUP(M87,scoring!$U$10:$AA$105,7,FALSE)-72*3 -> 72 | O87: Billy Horschel | P87: =+VLOOKUP(O87,scoring!$U$10:$AA$105,7,FALSE)-72*3 -> 98 | Q87: Cameron Young | R87: =+VLOOKUP(Q87,scoring!$U$10:$AA$105,7,FALSE)-72*3 -> 100 | S87: Jhonattan Vegas | T87: =+VLOOKUP(S87,scoring!$U$10:$AA$105,7,FALSE)-72*3 -> 99 | U87: =IFERROR(SMALL(E87:T87,1)+SMALL(E87:T87,2)+SMALL(E87:T87,3),IFERROR(SMALL(E87:T87,1)+SMALL(E87:T87,2),IFERROR(SMALL(E87:T87,1),"-"))) -> 197
B88: Every day is Moving Day | C88: James Fetch | D88: JF | E88: Jon Rahm | F88: =+VLOOKUP(E88,scoring!$U$10:$AA$105,7,FALSE)-72*3 -> 69 | G88: Bryson DeChambeau | H88: =+VLOOKUP(G88,scoring!$U$10:$AA$105,7,FALSE)-72*3 -> 65 | I88: Brooks Koepka | J88: =+VLOOKUP(I88,scoring!$U$10:$AA$105,7,FALSE)-72*3 -> 98 | K88: Jordan Spieth | L88: =+VLOOKUP(K88,scoring!$U$10:$AA$105,7,FALSE)-72*3 -> 69 | M88: Patrick Reed | N88: =+VLOOKUP(M88,scoring!$U$10:$AA$105,7,FALSE)-72*3 -> 63 | O88: Justin Rose | P88: =+VLOOKUP(O88,scoring!$U$10:$AA$105,7,FALSE)-72*3 -> 61 | Q88: Nicolai Højgaard | R88: =+VLOOKUP(Q88,scoring!$U$10:$AA$105,7,FALSE)-72*3 -> 99 | S88: Harris English | T88: =+VLOOKUP(S88,scoring!$U$10:$AA$105,7,FALSE)-72*3 -> 68 | U88: =IFERROR(SMALL(E88:T88,1)+SMALL(E88:T88,2)+SMALL(E88:T88,3),IFERROR(SMALL(E88:T88,1)+SMALL(E88:T88,2),IFERROR(SMALL(E88:T88,1),"-"))) -> 189
B89: TheProperLuncher | C89: Charles Ouellett | D89: CO | E89: Ludvig Aberg | F89: =+VLOOKUP(E89,scoring!$U$10:$AA$105,7,FALSE)-72*3 -> 66 | G89: Ludvig Aberg | H89: =+VLOOKUP(G89,scoring!$U$10:$AA$105,7,FALSE)-72*3 -> 66 | I89: Ludvig Aberg | J89: =+VLOOKUP(I89,scoring!$U$10:$AA$105,7,FALSE)-72*3 -> 66 | K89: Cameron Smith | L89: =+VLOOKUP(K89,scoring!$U$10:$AA$105,7,FALSE)-72*3 -> 98 | M89: Corey Conners | N89: =+VLOOKUP(M89,scoring!$U$10:$AA$105,7,FALSE)-72*3 -> 67 | O89: No Player | P89: =+VLOOKUP(O89,scoring!$U$10:$AA$105,7,FALSE)-72*3 -> 111 | Q89: No Player | R89: =+VLOOKUP(Q89,scoring!$U$10:$AA$105,7,FALSE)-72*3 -> 111 | S89: No Player | T89: =+VLOOKUP(S89,scoring!$U$10:$AA$105,7,FALSE)-72*3 -> 111 | U89: =IFERROR(SMALL(E89:T89,1)+SMALL(E89:T89,2)+SMALL(E89:T89,3),IFERROR(SMALL(E89:T89,1)+SMALL(E89:T89,2),IFERROR(SMALL(E89:T89,1),"-"))) -> 198
B90: MullinsDoubles | C90: Andy Mullins | D90: AM | E90: Bryson DeChambeau | F90: =+VLOOKUP(E90,scoring!$U$10:$AA$105,7,FALSE)-72*3 -> 65 | G90: Bryson DeChambeau | H90: =+VLOOKUP(G90,scoring!$U$10:$AA$105,7,FALSE)-72*3 -> 65 | I90: Joaquin Niemann | J90: =+VLOOKUP(I90,scoring!$U$10:$AA$105,7,FALSE)-72*3 -> 72 | K90: Joaquin Niemann | L90: =+VLOOKUP(K90,scoring!$U$10:$AA$105,7,FALSE)-72*3 -> 72 | M90: Robert MacIntyre | N90: =+VLOOKUP(M90,scoring!$U$10:$AA$105,7,FALSE)-72*3 -> 99 | O90: Robert MacIntyre | P90: =+VLOOKUP(O90,scoring!$U$10:$AA$105,7,FALSE)-72*3 -> 99 | Q90: No Player | R90: =+VLOOKUP(Q90,scoring!$U$10:$AA$105,7,FALSE)-72*3 -> 111 | S90: No Player | T90: =+VLOOKUP(S90,scoring!$U$10:$AA$105,7,FALSE)-72*3 -> 111 | U90: =IFERROR(SMALL(E90:T90,1)+SMALL(E90:T90,2)+SMALL(E90:T90,3),IFERROR(SMALL(E90:T90,1)+SMALL(E90:T90,2),IFERROR(SMALL(E90:T90,1),"-"))) -> 202

Sheet Round 4 Scores
A1: Round 4
A2: Team # | B2: Team | C2: Captain | D2: Initials | E2: Golfer 1 | G2: Golfer 2 | I2: Golfer 3 | K2: Golfer 4 | M2: Golfer 5 | O2: Golfer 6 | Q2: Golfer 7 | S2: Golfer 8 | U2: SCORE
A3: 6 | B3: Fire Nico | C3: Dan Lahrman | D3: DL | E3: Viktor Hovland | F3: =+VLOOKUP(E3,scoring!$U$10:$AA$105,6,FALSE)-72 -> 1 | G3: Viktor Hovland | H3: =+VLOOKUP(G3,scoring!$U$10:$AA$105,6,FALSE)-72 -> 1 | I3: Jordan Spieth | J3: =+VLOOKUP(I3,scoring!$U$10:$AA$105,6,FALSE)-72 -> -2 | K3: Jordan Spieth | L3: =+VLOOKUP(K3,scoring!$U$10:$AA$105,6,FALSE)-72 -> -2 | M3: Hideki Matsuyama | N3: =+VLOOKUP(M3,scoring!$U$10:$AA$105,6,FALSE)-72 -> -6 | O3: Hideki Matsuyama | P3: =+VLOOKUP(O3,scoring!$U$10:$AA$105,6,FALSE)-72 -> -6 | Q3: Jason Day | R3: =+VLOOKUP(Q3,scoring!$U$10:$AA$105,6,FALSE)-72 -> 0 | S3: Jason Day | T3: =+VLOOKUP(S3,scoring!$U$10:$AA$105,6,FALSE)-72 -> 0 | U3: =IFERROR(SMALL(E3:T3,1)+SMALL(E3:T3,2)+SMALL(E3:T3,3),IFERROR(SMALL(E3:T3,1)+SMALL(E3:T3,2),IFERROR(SMALL(E3:T3,1),"-"))) -> -14
A4: 11 | B4: Every day is Moving Day | C4: James Fetch | D4: JF | E4: Jon Rahm | F4: =+VLOOKUP(E4,scoring!$U$10:$AA$105,6,FALSE)-72 -> -3 | G4: Bryson DeChambeau | H4: =+VLOOKUP(G4,scoring!$U$10:$AA$105,6,FALSE)-72 -> 3 | I4: Brooks Koepka | J4: =+VLOOKUP(I4,scoring!$U$10:$AA$105,6,FALSE)-72 -> 13 | K4: Jordan Spieth | L4: =+VLOOKUP(K4,scoring!$U$10:$AA$105,6,FALSE)-72 -> -2 | M4: Patrick Reed | N4: =+VLOOKUP(M4,scoring!$U$10:$AA$105,6,FALSE)-72 -> -3 | O4: Justin Rose | P4: =+VLOOKUP(O4,scoring!$U$10:$AA$105,6,FALSE)-72 -> -6 | Q4: Nicolai Højgaard | R4: =+VLOOKUP(Q4,scoring!$U$10:$AA$105,6,FALSE)-72 -> 13 | S4: Harris English | T4: =+VLOOKUP(S4,scoring!$U$10:$AA$105,6,FALSE)-72 -> -4 | U4: =IFERROR(SMALL(E4:T4,1)+SMALL(E4:T4,2)+SMALL(E4:T4,3),IFERROR(SMALL(E4:T4,1)+SMALL(E4:T4,2),IFERROR(SMALL(E4:T4,1),"-"))) -> -13
A5: 33 | B5: Ty Webb's illegitimate stepchild | C5: Tom Nelson | D5: TN | E5: Ludvig Aberg | F5: =+VLOOKUP(E5,scoring!$U$10:$AA$105,6,FALSE)-72 -> 0 | G5: Ludvig Aberg | H5: =+VLOOKUP(G5,scoring!$U$10:$AA$105,6,FALSE)-72 -> 0 | I5: Justin Rose | J5: =+VLOOKUP(I5,scoring!$U$10:$AA$105,6,FALSE)-72 -> -6 | K5: Patrick Reed | L5: =+VLOOKUP(K5,scoring!$U$10:$AA$105,6,FALSE)-72 -> -3 | M5: Justin Thomas | N5: =+VLOOKUP(M5,scoring!$U$10:$AA$105,6,FALSE)-72 -> -2 | O5: J. J. Spaun | P5: =+VLOOKUP(O5,scoring!$U$10:$AA$105,6,FALSE)-72 -> 3 | Q5: Bubba Watson | R5: =+VLOOKUP(Q5,scoring!$U$10:$AA$105,6,FALSE)-72 -> -4 | S5: Tony Finau | T5: =+VLOOKUP(S5,scoring!$U$10:$AA$105,6,FALSE)-72 -> 13 | U5: =IFERROR(SMALL(E5:T5,1)+SMALL(E5:T5,2)+SMALL(E5:T5,3),IFERROR(SMALL(E5:T5,1)+SMALL(E5:T5,2),IFERROR(SMALL(E5:T5,1),"-"))) -> -13
A6: 31 | B6: Hello Friends | C6: Norm Boucher | D6: NB | E6: Collin Morikawa | F6: =+VLOOKUP(E6,scoring!$U$10:$AA$105,6,FALSE)-72 -> 0 | G6: Xander Schauffele | H6: =+VLOOKUP(G6,scoring!$U$10:$AA$105,6,FALSE)-72 -> -1 | I6: Brooks Koepka | J6: =+VLOOKUP(I6,scoring!$U$10:$AA$105,6,FALSE)-72 -> 13 | K6: Jordan Spieth | L6: =+VLOOKUP(K6,scoring!$U$10:$AA$105,6,FALSE)-72 -> -2 | M6: Hideki Matsuyama | N6: =+VLOOKUP(M6,scoring!$U$10:$AA$105,6,FALSE)-72 -> -6 | O6: Brian Campbell | P6: =+VLOOKUP(O6,scoring!$U$10:$AA$105,6,FALSE)-72 -> -4 | Q6: No Player | R6: =+VLOOKUP(Q6,scoring!$U$10:$AA$105,6,FALSE)-72 -> 14 | S6: No Player | T6: =+VLOOKUP(S6,scoring!$U$10:$AA$105,6,FALSE)-72 -> 14 | U6: =IFERROR(SMALL(E6:T6,1)+SMALL(E6:T6,2)+SMALL(E6:T6,3),IFERROR(SMALL(E6:T6,1)+SMALL(E6:T6,2),IFERROR(SMALL(E6:T6,1),"-"))) -> -12
A7: 3 | B7: Minnesota Miracle | C7: Thad Williams | D7: TW | E7: Collin Morikawa | F7: =+VLOOKUP(E7,scoring!$U$10:$AA$105,6,FALSE)-72 -> 0 | G7: Hideki Matsuyama | H7: =+VLOOKUP(G7,scoring!$U$10:$AA$105,6,FALSE)-72 -> -6 | I7: Hideki Matsuyama | J7: =+VLOOKUP(I7,scoring!$U$10:$AA$105,6,FALSE)-72 -> -6 | K7: Brooks Koepka | L7: =+VLOOKUP(K7,scoring!$U$10:$AA$105,6,FALSE)-72 -> 13 | M7: Robert MacIntyre | N7: =+VLOOKUP(M7,scoring!$U$10:$AA$105,6,FALSE)-72 -> 13 | O7: Will Zalatoris | P7: =+VLOOKUP(O7,scoring!$U$10:$AA$105,6,FALSE)-72 -> 13 | Q7: Phil Mickelson | R7: =+VLOOKUP(Q7,scoring!$U$10:$AA$105,6,FALSE)-72 -> 13 | S7: Laurie Canter | T7: =+VLOOKUP(S7,scoring!$U$10:$AA$105,6,FALSE)-72 -> 13 | U7: =IFERROR(SMALL(E7:T7,1)+SMALL(E7:T7,2)+SMALL(E7:T7,3),IFERROR(SMALL(E7:T7,1)+SMALL(E7:T7,2),IFERROR(SMALL(E7:T7,1),"-"))) -> -12
A8: 4 | B8: Play the fade | C8: Dan Riordan | D8: DR | E8: Ludvig Aberg | F8: =+VLOOKUP(E8,scoring!$U$10:$AA$105,6,FALSE)-72 -> 0 | G8: Justin Thomas | H8: =+VLOOKUP(G8,scoring!$U$10:$AA$105,6,FALSE)-72 -> -2 | I8: Hideki Matsuyama | J8: =+VLOOKUP(I8,scoring!$U$10:$AA$105,6,FALSE)-72 -> -6 | K8: Russell Henley | L8: =+VLOOKUP(K8,scoring!$U$10:$AA$105,6,FALSE)-72 -> 13 | M8: Akshay Bhatia | N8: =+VLOOKUP(M8,scoring!$U$10:$AA$105,6,FALSE)-72 -> -1 | O8: Akshay Bhatia | P8: =+VLOOKUP(O8,scoring!$U$10:$AA$105,6,FALSE)-72 -> -1 | Q8: Corey Conners | R8: =+VLOOKUP(Q8,scoring!$U$10:$AA$105,6,FALSE)-72 -> 3 | S8: Lucas Glover | T8: =+VLOOKUP(S8,scoring!$U$10:$AA$105,6,FALSE)-72 -> 13 | U8: =IFERROR(SMALL(E8:T8,1)+SMALL(E8:T8,2)+SMALL(E8:T8,3),IFERROR(SMALL(E8:T8,1)+SMALL(E8:T8,2),IFERROR(SMALL(E8:T8,1),"-"))) -> -9
A9: 26 | B9: The Tremendous Slouches | C9: Mike Wands | D9: MW | E9: Jon Rahm | F9: =+VLOOKUP(E9,scoring!$U$10:$AA$105,6,FALSE)-72 -> -3 | G9: Ludvig Aberg | H9: =+VLOOKUP(G9,scoring!$U$10:$AA$105,6,FALSE)-72 -> 0 | I9: Hideki Matsuyama | J9: =+VLOOKUP(I9,scoring!$U$10:$AA$105,6,FALSE)-72 -> -6 | K9: Brooks Koepka | L9: =+VLOOKUP(K9,scoring!$U$10:$AA$105,6,FALSE)-72 -> 13 | M9: Cameron Smith | N9: =+VLOOKUP(M9,scoring!$U$10:$AA$105,6,FALSE)-72 -> 13 | O9: No Player | P9: =+VLOOKUP(O9,scoring!$U$10:$AA$105,6,FALSE)-72 -> 14 | Q9: No Player | R9: =+VLOOKUP(Q9,scoring!$U$10:$AA$105,6,FALSE)-72 -> 14 | S9: No Player | T9: =+VLOOKUP(S9,scoring!$U$10:$AA$105,6,FALSE)-72 -> 14 | U9: =IFERROR(SMALL(E9:T9,1)+SMALL(E9:T9,2)+SMALL(E9:T9,3),IFERROR(SMALL(E9:T9,1)+SMALL(E9:T9,2),IFERROR(SMALL(E9:T9,1),"-"))) -> -9
A10: 19 | B10: ZWill #2 | C10: Zach Williams | D10: ZW | E10: Rory McIlroy | F10: =+VLOOKUP(E10,scoring!$U$10:$AA$105,6,FALSE)-72 -> 1 | G10: Min Woo Lee | H10: =+VLOOKUP(G10,scoring!$U$10:$AA$105,6,FALSE)-72 -> 2 | I10: Min Woo Lee | J10: =+VLOOKUP(I10,scoring!$U$10:$AA$105,6,FALSE)-72 -> 2 | K10: Akshay Bhatia | L10: =+VLOOKUP(K10,scoring!$U$10:$AA$105,6,FALSE)-72 -> -1 | M10: Akshay Bhatia | N10: =+VLOOKUP(M10,scoring!$U$10:$AA$105,6,FALSE)-72 -> -1 | O10: Justin Rose | P10: =+VLOOKUP(O10,scoring!$U$10:$AA$105,6,FALSE)-72 -> -6 | Q10: No Player | R10: =+VLOOKUP(Q10,scoring!$U$10:$AA$105,6,FALSE)-72 -> 14 | S10: No Player | T10: =+VLOOKUP(S10,scoring!$U$10:$AA$105,6,FALSE)-72 -> 14 | U10: =IFERROR(SMALL(E10:T10,1)+SMALL(E10:T10,2)+SMALL(E10:T10,3),IFERROR(SMALL(E10:T10,1)+SMALL(E10:T10,2),IFERROR(SMALL(E10:T10,1),"-"))) -> -8
